{
 "cells": [
  {
   "cell_type": "code",
   "execution_count": 1,
   "metadata": {},
   "outputs": [
    {
     "name": "stderr",
     "output_type": "stream",
     "text": [
      "2023-08-08 09:23:16.628259: I tensorflow/tsl/cuda/cudart_stub.cc:28] Could not find cuda drivers on your machine, GPU will not be used.\n",
      "2023-08-08 09:23:16.688125: I tensorflow/tsl/cuda/cudart_stub.cc:28] Could not find cuda drivers on your machine, GPU will not be used.\n",
      "2023-08-08 09:23:16.689494: I tensorflow/core/platform/cpu_feature_guard.cc:182] This TensorFlow binary is optimized to use available CPU instructions in performance-critical operations.\n",
      "To enable the following instructions: AVX2 FMA, in other operations, rebuild TensorFlow with the appropriate compiler flags.\n",
      "2023-08-08 09:23:17.765825: W tensorflow/compiler/tf2tensorrt/utils/py_utils.cc:38] TF-TRT Warning: Could not find TensorRT\n"
     ]
    }
   ],
   "source": [
    "import tensorflow as tf\n",
    "import pandas as pd\n",
    "import keras\n",
    "from keras.layers import Dense\n",
    "from scikeras.wrappers import KerasClassifier\n",
    "import numpy as np\n",
    "from sklearn.model_selection import train_test_split\n",
    "from sklearn.preprocessing import StandardScaler\n",
    "from sklearn.model_selection import GridSearchCV\n",
    "\n",
    "df = pd.read_csv(\"music.csv\")"
   ]
  },
  {
   "cell_type": "code",
   "execution_count": 2,
   "metadata": {},
   "outputs": [
    {
     "name": "stdout",
     "output_type": "stream",
     "text": [
      "Training Features Shape: (749, 23)\n",
      "Training Labels Shape: (749, 10)\n",
      "Testing Features Shape: (250, 23)\n",
      "Testing Labels Shape: (250, 10)\n"
     ]
    }
   ],
   "source": [
    "# features = pd.read_csv('music.xls')\n",
    "features = df\n",
    "# One-hot encode\n",
    "labels = pd.get_dummies(features['label'])\n",
    "# enleve les labels des features\n",
    "features = features.drop('label', axis = 1)\n",
    "# sauvegarde la liste des features\n",
    "feature_list = list(features.columns)\n",
    "# conversion en numpy array\n",
    "features = np.array(features)\n",
    "\n",
    "train_features, test_features, train_labels, test_labels = train_test_split(features, labels, test_size=0.25, random_state = 0)\n",
    "print('Training Features Shape:', train_features.shape)\n",
    "print('Training Labels Shape:', train_labels.shape)\n",
    "print('Testing Features Shape:', test_features.shape)\n",
    "print('Testing Labels Shape:', test_labels.shape)\n",
    "\n",
    "# scaling\n",
    "sc = StandardScaler()\n",
    "train_features = sc.fit_transform(train_features)\n",
    "test_features = sc.transform(test_features)"
   ]
  },
  {
   "cell_type": "code",
   "execution_count": 3,
   "metadata": {},
   "outputs": [
    {
     "name": "stderr",
     "output_type": "stream",
     "text": [
      "2023-08-08 09:23:20.505072: I tensorflow/tsl/cuda/cudart_stub.cc:28] Could not find cuda drivers on your machine, GPU will not be used.\n",
      "2023-08-08 09:23:20.545535: I tensorflow/tsl/cuda/cudart_stub.cc:28] Could not find cuda drivers on your machine, GPU will not b2023-08-08 09:23:20.545535: I tensorflow/tsl/cuda/cudart_stub.cc:28] Could not find cuda drivers on your machine, GPU will not be used.\n",
      "e used.\n",
      "2023-08-08 09:23:20.564399: I tensorflow/tsl/cuda/cudart_stub.cc:28] Could not find cuda drivers on your machine, GPU will not be used.\n",
      "2023-08-08 09:23:20.565030: I tensorflow/core/platform/cpu_feature_guard.cc:182] This TensorFlow binary is optimized to use available CPU instructions in performance-critical operations.\n",
      "To enable the following instructions: AVX2 FMA, in other operations, rebuild TensorFlow with the appropriate compiler flags.\n",
      "2023-08-08 09:23:20.568261: I tensorflow/tsl/cuda/cudart_stub.cc:28] Could not find cuda drivers on your machine, GPU will not be used.\n",
      "2023-08-08 09:23:20.577047: I tensorflow/tsl/cuda/cudart_stub.cc:28] Could not find cuda drivers on your machine, GPU will not be used.\n",
      "2023-08-08 09:23:20.595152: I tensorflow/tsl/cuda/cudart_stub.cc:28] Could not find cuda drivers on your machine, GPU will not be used.\n",
      "2023-08-08 09:23:20.604778: I tensorflow/tsl/cuda/cudart_stub.cc:28] Could not find cuda drivers on your machine, GPU will not be used.\n",
      "2023-08-08 09:23:20.605177: I tensorflow/core/platform/cpu_feature_guard.cc:182] This TensorFlow binary is optimized to use available CPU instructions in performance-critical operations.\n",
      "To enable the following instructions: AVX2 FMA, in other operations, rebuild TensorFlow with the appropriate compiler flags.\n",
      "2023-08-08 09:23:20.607205: I tensorflow/tsl/cuda/cudart_stub.cc:28] Could not find cuda drivers on your machine, GPU will not be used.\n",
      "2023-08-08 09:23:20.607644: I tensorflow/core/platform/cpu_feature_guard.cc:182] This TensorFlow binary is optimized to use available CPU instructions in performance-critical operations.\n",
      "To enable the following instructions: AVX2 FMA, in other operations, rebuild TensorFlow with the appropriate compiler flags.\n",
      "2023-08-08 09:23:20.616044: I tensorflow/tsl/cuda/cudart_stub.cc:28] Could not find cuda drivers on your machine, GPU will not be used.\n",
      "2023-08-08 09:23:20.618383: I tensorflow/tsl/cuda/cudart_stub.cc:28] Could not find cuda drivers on your machine, GPU will not be used.\n",
      "2023-08-08 09:23:20.623815: I tensorflow/tsl/cuda/cudart_stub.cc:28] Could not find cuda drivers on your machine, GPU will not be used.\n",
      "2023-08-08 09:23:20.624241: I tensorflow/core/platform/cpu_feature_guard.cc:182] This TensorFlow binary is optimized to use available CPU instructions in performance-critical operations.\n",
      "To enable the following instructions: AVX2 FMA, in other operations, rebuild TensorFlow with the appropriate compiler flags.\n",
      "2023-08-08 09:23:20.634898: I tensorflow/tsl/cuda/cudart_stub.cc:28] Could not find cuda drivers on your machine, GPU will not be used.\n",
      "2023-08-08 09:23:20.635355: I tensorflow/core/platform/cpu_feature_guard.cc:182] This TensorFlow binary is optimized to use available CPU instructions in performance-critical operations.\n",
      "To enable the following instructions: AVX2 FMA, in other operations, rebuild TensorFlow with the appropriate compiler flags.\n",
      "2023-08-08 09:23:20.651724: I tensorflow/tsl/cuda/cudart_stub.cc:28] Could not find cuda drivers on your machine, GPU will not be used.\n",
      "2023-08-08 09:23:20.652134: I tensorflow/core/platform/cpu_feature_guard.cc:182] This TensorFlow binary is optimized to use available CPU instructions in performance-critical operations.\n",
      "To enable the following instructions: AVX2 FMA, in other operations, rebuild TensorFlow with the appropriate compiler flags.\n",
      "2023-08-08 09:23:20.675949: I tensorflow/tsl/cuda/cudart_stub.cc:28] Could not find cuda drivers on your machine, GPU will not be used.\n",
      "2023-08-08 09:23:20.676619: I tensorflow/core/platform/cpu_feature_guard.cc:182] This TensorFlow binary is optimized to use available CPU instructions in performance-critical operations.\n",
      "To enable the following instructions: AVX2 FMA, in other operations, rebuild TensorFlow with the appropriate compiler flags.\n",
      "2023-08-08 09:23:20.687267: I tensorflow/tsl/cuda/cudart_stub.cc:28] Could not find cuda drivers on your machine, GPU will not be used.\n",
      "2023-08-08 09:23:20.687795: I tensorflow/core/platform/cpu_feature_guard.cc:182] This TensorFlow binary is optimized to use available CPU instructions in performance-critical operations.\n",
      "To enable the following instructions: AVX2 FMA, in other operations, rebuild TensorFlow with the appropriate compiler flags.\n",
      "2023-08-08 09:23:20.806513: I tensorflow/tsl/cuda/cudart_stub.cc:28] Could not find cuda drivers on your machine, GPU will not be used.\n",
      "2023-08-08 09:23:20.879805: I tensorflow/tsl/cuda/cudart_stub.cc:28] Could not find cuda drivers on your machine, GPU will not be used.\n",
      "2023-08-08 09:23:20.880445: I tensorflow/core/platform/cpu_feature_guard.cc:182] This TensorFlow binary is optimized to use available CPU instructions in performance-critical operations.\n",
      "To enable the following instructions: AVX2 FMA, in other operations, rebuild TensorFlow with the appropriate compiler flags.\n",
      "2023-08-08 09:23:21.768572: W tensorflow/compiler/tf2tensorrt/utils/py_utils.cc:38] TF-TRT Warning: Could not find TensorRT\n",
      "2023-08-08 09:23:21.807526: W tensorflow/compiler/tf2tensorrt/utils/py_utils.cc:38] TF-TRT Warning: Could not find TensorRT\n",
      "2023-08-08 09:23:21.823603: W tensorflow/compiler/tf2tensorrt/utils/py_utils.cc:38] TF-TRT Warning: Could not find TensorRT\n",
      "2023-08-08 09:23:21.827665: W tensorflow/compiler/tf2tensorrt/utils/py_utils.cc:38] TF-TRT Warning: Could not find TensorRT\n",
      "2023-08-08 09:23:21.847127: W tensorflow/compiler/tf2tensorrt/utils/py_utils.cc:38] TF-TRT Warning: Could not find TensorRT\n",
      "2023-08-08 09:23:21.881381: W tensorflow/compiler/tf2tensorrt/utils/py_utils.cc:38] TF-TRT Warning: Could not find TensorRT\n",
      "2023-08-08 09:23:21.888202: W tensorflow/compiler/tf2tensorrt/utils/py_utils.cc:38] TF-TRT Warning: Could not find TensorRT\n",
      "2023-08-08 09:23:22.267083: W tensorflow/compiler/tf2tensorrt/utils/py_utils.cc:38] TF-TRT Warning: Could not find TensorRT\n",
      "2023-08-08 09:23:22.472367: W tensorflow/compiler/tf2tensorrt/utils/py_utils.cc:38] TF-TRT Warning: Could not find TensorRT\n",
      "/home/payetquentin/Documents/workspace/briefs/S9_music/labos/.venv/lib/python3.11/site-packages/scikeras/wrappers.py:915: UserWarning: ``build_fn`` will be renamed to ``model`` in a future release, at which point use of ``build_fn`` will raise an Error instead.\n",
      "  X, y = self._initialize(X, y)\n",
      "/home/payetquentin/Documents/workspace/briefs/S9_music/labos/.venv/lib/python3.11/site-packages/scikeras/wrappers.py:915: UserWarning: ``build_fn`` will be renamed to ``model`` in a future release, at which point use of ``build_fn`` will raise an Error instead.\n",
      "  X, y = self._initialize(X, y)\n",
      "2023-08-08 09:23:23.016460: I tensorflow/compiler/xla/stream_executor/cuda/cuda_gpu_executor.cc:995] successful NUMA node read from SysFS had negative value (-1), but there must be at least one NUMA node, so returning NUMA node zero. See more at https://github.com/torvalds/linux/blob/v6.0/Documentation/ABI/testing/sysfs-bus-pci#L344-L355\n",
      "2023-08-08 09:23:23.017447: W tensorflow/core/common_runtime/gpu/gpu_device.cc:1960] Cannot dlopen some GPU libraries. Please make sure the missing libraries mentioned above are installed properly if you would like to use GPU. Follow the guide at https://www.tensorflow.org/install/gpu for how to download and setup the required libraries for your platform.\n",
      "Skipping registering GPU devices...\n",
      "2023-08-08 09:23:23.026959: I tensorflow/compiler/xla/stream_executor/cuda/cuda_gpu_executor.cc:995] successful NUMA node read from SysFS had negative value (-1), but there must be at least one NUMA node, so returning NUMA node zero. See more at https://github.com/torvalds/linux/blob/v6.0/Documentation/ABI/testing/sysfs-bus-pci#L344-L355\n",
      "2023-08-08 09:23:23.027680: W tensorflow/core/common_runtime/gpu/gpu_device.cc:1960] Cannot dlopen some GPU libraries. Please make sure the missing libraries mentioned above are installed properly if you would like to use GPU. Follow the guide at https://www.tensorflow.org/install/gpu for how to download and setup the required libraries for your platform.\n",
      "Skipping registering GPU devices...\n",
      "/home/payetquentin/Documents/workspace/briefs/S9_music/labos/.venv/lib/python3.11/site-packages/scikeras/wrappers.py:915: UserWarning: ``build_fn`` will be renamed to ``model`` in a future release, at which point use of ``build_fn`` will raise an Error instead.\n",
      "  X, y = self._initialize(X, y)\n",
      "/home/payetquentin/Documents/workspace/briefs/S9_music/labos/.venv/lib/python3.11/site-packages/scikeras/wrappers.py:915: UserWarning: ``build_fn`` will be renamed to ``model`` in a future release, at which point use of ``build_fn`` will raise an Error instead.\n",
      "  X, y = self._initialize(X, y)\n",
      "/home/payetquentin/Documents/workspace/briefs/S9_music/labos/.venv/lib/python3.11/site-packages/scikeras/wrappers.py:915: UserWarning: ``build_fn`` will be renamed to ``model`` in a future release, at which point use of ``build_fn`` will raise an Error instead.\n",
      "  X, y = self._initialize(X, y)\n",
      "2023-08-08 09:23:23.054374: I tensorflow/compiler/xla/stream_executor/cuda/cuda_gpu_executor.cc:995] successful NUMA node read from SysFS had negative value (-1), but there must be at least one NUMA node, so returning NUMA node zero. See more at https://github.com/torvalds/linux/blob/v6.0/Documentation/ABI/testing/sysfs-bus-pci#L344-L355\n",
      "2023-08-08 09:23:23.055299: W tensorflow/core/common_runtime/gpu/gpu_device.cc:1960] Cannot dlopen some GPU libraries. Please make sure the missing libraries mentioned above are installed properly if you would like to use GPU. Follow the guide at https://www.tensorflow.org/install/gpu for how to download and setup the required libraries for your platform.\n",
      "Skipping registering GPU devices...\n",
      "2023-08-08 09:23:23.060084: I tensorflow/compiler/xla/stream_executor/cuda/cuda_gpu_executor.cc:995] successful NUMA node read from SysFS had negative value (-1), but there must be at least one NUMA node, so returning NUMA node zero. See more at https://github.com/torvalds/linux/blob/v6.0/Documentation/ABI/testing/sysfs-bus-pci#L344-L355\n",
      "2023-08-08 09:23:23.060934: W tensorflow/core/common_runtime/gpu/gpu_device.cc:1960] Cannot dlopen some GPU libraries. Please make sure the missing libraries mentioned above are installed properly if you would like to use GPU. Follow the guide at https://www.tensorflow.org/install/gpu for how to download and setup the required libraries for your platform.\n",
      "Skipping registering GPU devices...\n",
      "2023-08-08 09:23:23.064376: I tensorflow/compiler/xla/stream_executor/cuda/cuda_gpu_executor.cc:995] successful NUMA node read from SysFS had negative value (-1), but there must be at least one NUMA node, so returning NUMA node zero. See more at https://github.com/torvalds/linux/blob/v6.0/Documentation/ABI/testing/sysfs-bus-pci#L344-L355\n",
      "2023-08-08 09:23:23.065133: W tensorflow/core/common_runtime/gpu/gpu_device.cc:1960] Cannot dlopen some GPU libraries. Please make sure the missing libraries mentioned above are installed properly if you would like to use GPU. Follow the guide at https://www.tensorflow.org/install/gpu for how to download and setup the required libraries for your platform.\n",
      "Skipping registering GPU devices...\n",
      "/home/payetquentin/Documents/workspace/briefs/S9_music/labos/.venv/lib/python3.11/site-packages/scikeras/wrappers.py:915: UserWarning: ``build_fn`` will be renamed to ``model`` in a future release, at which point use of ``build_fn`` will raise an Error instead.\n",
      "  X, y = self._initialize(X, y)\n",
      "/home/payetquentin/Documents/workspace/briefs/S9_music/labos/.venv/lib/python3.11/site-packages/scikeras/wrappers.py:915: UserWarning: ``build_fn`` will be renamed to ``model`` in a future release, at which point use of ``build_fn`` will raise an Error instead.\n",
      "  X, y = self._initialize(X, y)\n",
      "2023-08-08 09:23:23.098648: I tensorflow/compiler/xla/stream_executor/cuda/cuda_gpu_executor.cc:995] successful NUMA node read from SysFS had negative value (-1), but there must be at least one NUMA node, so returning NUMA node zero. See more at https://github.com/torvalds/linux/blob/v6.0/Documentation/ABI/testing/sysfs-bus-pci#L344-L355\n",
      "2023-08-08 09:23:23.099498: W tensorflow/core/common_runtime/gpu/gpu_device.cc:1960] Cannot dlopen some GPU libraries. Please make sure the missing libraries mentioned above are installed properly if you would like to use GPU. Follow the guide at https://www.tensorflow.org/install/gpu for how to download and setup the required libraries for your platform.\n",
      "Skipping registering GPU devices...\n",
      "2023-08-08 09:23:23.109126: I tensorflow/compiler/xla/stream_executor/cuda/cuda_gpu_executor.cc:995] successful NUMA node read from SysFS had negative value (-1), but there must be at least one NUMA node, so returning NUMA node zero. See more at https://github.com/torvalds/linux/blob/v6.0/Documentation/ABI/testing/sysfs-bus-pci#L344-L355\n",
      "2023-08-08 09:23:23.110472: W tensorflow/core/common_runtime/gpu/gpu_device.cc:1960] Cannot dlopen some GPU libraries. Please make sure the missing libraries mentioned above are installed properly if you would like to use GPU. Follow the guide at https://www.tensorflow.org/install/gpu for how to download and setup the required libraries for your platform.\n",
      "Skipping registering GPU devices...\n",
      "/home/payetquentin/Documents/workspace/briefs/S9_music/labos/.venv/lib/python3.11/site-packages/scikeras/wrappers.py:915: UserWarning: ``build_fn`` will be renamed to ``model`` in a future release, at which point use of ``build_fn`` will raise an Error instead.\n",
      "  X, y = self._initialize(X, y)\n",
      "2023-08-08 09:23:23.625101: I tensorflow/compiler/xla/stream_executor/cuda/cuda_gpu_executor.cc:995] successful NUMA node read from SysFS had negative value (-1), but there must be at least one NUMA node, so returning NUMA node zero. See more at https://github.com/torvalds/linux/blob/v6.0/Documentation/ABI/testing/sysfs-bus-pci#L344-L355\n",
      "2023-08-08 09:23:23.625507: W tensorflow/core/common_runtime/gpu/gpu_device.cc:1960] Cannot dlopen some GPU libraries. Please make sure the missing libraries mentioned above are installed properly if you would like to use GPU. Follow the guide at https://www.tensorflow.org/install/gpu for how to download and setup the required libraries for your platform.\n",
      "Skipping registering GPU devices...\n",
      "/home/payetquentin/Documents/workspace/briefs/S9_music/labos/.venv/lib/python3.11/site-packages/scikeras/wrappers.py:915: UserWarning: ``build_fn`` will be renamed to ``model`` in a future release, at which point use of ``build_fn`` will raise an Error instead.\n",
      "  X, y = self._initialize(X, y)\n",
      "2023-08-08 09:23:23.708790: I tensorflow/compiler/xla/stream_executor/cuda/cuda_gpu_executor.cc:995] successful NUMA node read from SysFS had negative value (-1), but there must be at least one NUMA node, so returning NUMA node zero. See more at https://github.com/torvalds/linux/blob/v6.0/Documentation/ABI/testing/sysfs-bus-pci#L344-L355\n",
      "2023-08-08 09:23:23.709314: W tensorflow/core/common_runtime/gpu/gpu_device.cc:1960] Cannot dlopen some GPU libraries. Please make sure the missing libraries mentioned above are installed properly if you would like to use GPU. Follow the guide at https://www.tensorflow.org/install/gpu for how to download and setup the required libraries for your platform.\n",
      "Skipping registering GPU devices...\n"
     ]
    },
    {
     "ename": "ValueError",
     "evalue": "\nAll the 9 fits failed.\nIt is very likely that your model is misconfigured.\nYou can try to debug the error by setting error_score='raise'.\n\nBelow are more details about the failures:\n--------------------------------------------------------------------------------\n1 fits failed with the following error:\nTraceback (most recent call last):\n  File \"/home/payetquentin/Documents/workspace/briefs/S9_music/labos/.venv/lib/python3.11/site-packages/sklearn/model_selection/_validation.py\", line 732, in _fit_and_score\n    estimator.fit(X_train, y_train, **fit_params)\n  File \"/home/payetquentin/Documents/workspace/briefs/S9_music/labos/.venv/lib/python3.11/site-packages/scikeras/wrappers.py\", line 1491, in fit\n    super().fit(X=X, y=y, sample_weight=sample_weight, **kwargs)\n  File \"/home/payetquentin/Documents/workspace/briefs/S9_music/labos/.venv/lib/python3.11/site-packages/scikeras/wrappers.py\", line 760, in fit\n    self._fit(\n  File \"/home/payetquentin/Documents/workspace/briefs/S9_music/labos/.venv/lib/python3.11/site-packages/scikeras/wrappers.py\", line 928, in _fit\n    self._fit_keras_model(\n  File \"/home/payetquentin/Documents/workspace/briefs/S9_music/labos/.venv/lib/python3.11/site-packages/scikeras/wrappers.py\", line 524, in _fit_keras_model\n    hist = self.model_.fit(x=X, y=y, **fit_args)\n           ^^^^^^^^^^^^^^^^^^^^^^^^^^^^^^^^^^^^^\n  File \"/home/payetquentin/Documents/workspace/briefs/S9_music/labos/.venv/lib/python3.11/site-packages/keras/src/utils/traceback_utils.py\", line 70, in error_handler\n    raise e.with_traceback(filtered_tb) from None\n  File \"/tmp/__autograph_generated_filevsyiuivp.py\", line 18, in tf__train_function\n    raise\nValueError: in user code:\n\n    File \"/home/payetquentin/Documents/workspace/briefs/S9_music/labos/.venv/lib/python3.11/site-packages/keras/src/engine/training.py\", line 1338, in train_function  *\n        return step_function(self, iterator)\n    File \"/home/payetquentin/Documents/workspace/briefs/S9_music/labos/.venv/lib/python3.11/site-packages/keras/src/engine/training.py\", line 1322, in step_function  **\n        outputs = model.distribute_strategy.run(run_step, args=(data,))\n    File \"/home/payetquentin/Documents/workspace/briefs/S9_music/labos/.venv/lib/python3.11/site-packages/keras/src/engine/training.py\", line 1303, in run_step  **\n        outputs = model.train_step(data)\n    File \"/home/payetquentin/Documents/workspace/briefs/S9_music/labos/.venv/lib/python3.11/site-packages/keras/src/engine/training.py\", line 1081, in train_step\n        loss = self.compute_loss(x, y, y_pred, sample_weight)\n    File \"/home/payetquentin/Documents/workspace/briefs/S9_music/labos/.venv/lib/python3.11/site-packages/keras/src/engine/training.py\", line 1139, in compute_loss\n        return self.compiled_loss(\n    File \"/home/payetquentin/Documents/workspace/briefs/S9_music/labos/.venv/lib/python3.11/site-packages/keras/src/engine/compile_utils.py\", line 265, in __call__\n        loss_value = loss_obj(y_t, y_p, sample_weight=sw)\n    File \"/home/payetquentin/Documents/workspace/briefs/S9_music/labos/.venv/lib/python3.11/site-packages/keras/src/losses.py\", line 142, in __call__\n        losses = call_fn(y_true, y_pred)\n    File \"/home/payetquentin/Documents/workspace/briefs/S9_music/labos/.venv/lib/python3.11/site-packages/keras/src/losses.py\", line 268, in call  **\n        return ag_fn(y_true, y_pred, **self._fn_kwargs)\n    File \"/home/payetquentin/Documents/workspace/briefs/S9_music/labos/.venv/lib/python3.11/site-packages/keras/src/losses.py\", line 2122, in categorical_crossentropy\n        return backend.categorical_crossentropy(\n    File \"/home/payetquentin/Documents/workspace/briefs/S9_music/labos/.venv/lib/python3.11/site-packages/keras/src/backend.py\", line 5560, in categorical_crossentropy\n        target.shape.assert_is_compatible_with(output.shape)\n\n    ValueError: Shapes (None, 1) and (None, 10) are incompatible\n\n\n--------------------------------------------------------------------------------\n1 fits failed with the following error:\nTraceback (most recent call last):\n  File \"/home/payetquentin/Documents/workspace/briefs/S9_music/labos/.venv/lib/python3.11/site-packages/sklearn/model_selection/_validation.py\", line 732, in _fit_and_score\n    estimator.fit(X_train, y_train, **fit_params)\n  File \"/home/payetquentin/Documents/workspace/briefs/S9_music/labos/.venv/lib/python3.11/site-packages/scikeras/wrappers.py\", line 1491, in fit\n    super().fit(X=X, y=y, sample_weight=sample_weight, **kwargs)\n  File \"/home/payetquentin/Documents/workspace/briefs/S9_music/labos/.venv/lib/python3.11/site-packages/scikeras/wrappers.py\", line 760, in fit\n    self._fit(\n  File \"/home/payetquentin/Documents/workspace/briefs/S9_music/labos/.venv/lib/python3.11/site-packages/scikeras/wrappers.py\", line 928, in _fit\n    self._fit_keras_model(\n  File \"/home/payetquentin/Documents/workspace/briefs/S9_music/labos/.venv/lib/python3.11/site-packages/scikeras/wrappers.py\", line 524, in _fit_keras_model\n    hist = self.model_.fit(x=X, y=y, **fit_args)\n           ^^^^^^^^^^^^^^^^^^^^^^^^^^^^^^^^^^^^^\n  File \"/home/payetquentin/Documents/workspace/briefs/S9_music/labos/.venv/lib/python3.11/site-packages/keras/src/utils/traceback_utils.py\", line 70, in error_handler\n    raise e.with_traceback(filtered_tb) from None\n  File \"/tmp/__autograph_generated_filewu0bjk1n.py\", line 18, in tf__train_function\n    raise\nValueError: in user code:\n\n    File \"/home/payetquentin/Documents/workspace/briefs/S9_music/labos/.venv/lib/python3.11/site-packages/keras/src/engine/training.py\", line 1338, in train_function  *\n        return step_function(self, iterator)\n    File \"/home/payetquentin/Documents/workspace/briefs/S9_music/labos/.venv/lib/python3.11/site-packages/keras/src/engine/training.py\", line 1322, in step_function  **\n        outputs = model.distribute_strategy.run(run_step, args=(data,))\n    File \"/home/payetquentin/Documents/workspace/briefs/S9_music/labos/.venv/lib/python3.11/site-packages/keras/src/engine/training.py\", line 1303, in run_step  **\n        outputs = model.train_step(data)\n    File \"/home/payetquentin/Documents/workspace/briefs/S9_music/labos/.venv/lib/python3.11/site-packages/keras/src/engine/training.py\", line 1081, in train_step\n        loss = self.compute_loss(x, y, y_pred, sample_weight)\n    File \"/home/payetquentin/Documents/workspace/briefs/S9_music/labos/.venv/lib/python3.11/site-packages/keras/src/engine/training.py\", line 1139, in compute_loss\n        return self.compiled_loss(\n    File \"/home/payetquentin/Documents/workspace/briefs/S9_music/labos/.venv/lib/python3.11/site-packages/keras/src/engine/compile_utils.py\", line 265, in __call__\n        loss_value = loss_obj(y_t, y_p, sample_weight=sw)\n    File \"/home/payetquentin/Documents/workspace/briefs/S9_music/labos/.venv/lib/python3.11/site-packages/keras/src/losses.py\", line 142, in __call__\n        losses = call_fn(y_true, y_pred)\n    File \"/home/payetquentin/Documents/workspace/briefs/S9_music/labos/.venv/lib/python3.11/site-packages/keras/src/losses.py\", line 268, in call  **\n        return ag_fn(y_true, y_pred, **self._fn_kwargs)\n    File \"/home/payetquentin/Documents/workspace/briefs/S9_music/labos/.venv/lib/python3.11/site-packages/keras/src/losses.py\", line 2122, in categorical_crossentropy\n        return backend.categorical_crossentropy(\n    File \"/home/payetquentin/Documents/workspace/briefs/S9_music/labos/.venv/lib/python3.11/site-packages/keras/src/backend.py\", line 5560, in categorical_crossentropy\n        target.shape.assert_is_compatible_with(output.shape)\n\n    ValueError: Shapes (None, 1) and (None, 10) are incompatible\n\n\n--------------------------------------------------------------------------------\n1 fits failed with the following error:\nTraceback (most recent call last):\n  File \"/home/payetquentin/Documents/workspace/briefs/S9_music/labos/.venv/lib/python3.11/site-packages/sklearn/model_selection/_validation.py\", line 732, in _fit_and_score\n    estimator.fit(X_train, y_train, **fit_params)\n  File \"/home/payetquentin/Documents/workspace/briefs/S9_music/labos/.venv/lib/python3.11/site-packages/scikeras/wrappers.py\", line 1491, in fit\n    super().fit(X=X, y=y, sample_weight=sample_weight, **kwargs)\n  File \"/home/payetquentin/Documents/workspace/briefs/S9_music/labos/.venv/lib/python3.11/site-packages/scikeras/wrappers.py\", line 760, in fit\n    self._fit(\n  File \"/home/payetquentin/Documents/workspace/briefs/S9_music/labos/.venv/lib/python3.11/site-packages/scikeras/wrappers.py\", line 928, in _fit\n    self._fit_keras_model(\n  File \"/home/payetquentin/Documents/workspace/briefs/S9_music/labos/.venv/lib/python3.11/site-packages/scikeras/wrappers.py\", line 524, in _fit_keras_model\n    hist = self.model_.fit(x=X, y=y, **fit_args)\n           ^^^^^^^^^^^^^^^^^^^^^^^^^^^^^^^^^^^^^\n  File \"/home/payetquentin/Documents/workspace/briefs/S9_music/labos/.venv/lib/python3.11/site-packages/keras/src/utils/traceback_utils.py\", line 70, in error_handler\n    raise e.with_traceback(filtered_tb) from None\n  File \"/tmp/__autograph_generated_filexz392npo.py\", line 18, in tf__train_function\n    raise\nValueError: in user code:\n\n    File \"/home/payetquentin/Documents/workspace/briefs/S9_music/labos/.venv/lib/python3.11/site-packages/keras/src/engine/training.py\", line 1338, in train_function  *\n        return step_function(self, iterator)\n    File \"/home/payetquentin/Documents/workspace/briefs/S9_music/labos/.venv/lib/python3.11/site-packages/keras/src/engine/training.py\", line 1322, in step_function  **\n        outputs = model.distribute_strategy.run(run_step, args=(data,))\n    File \"/home/payetquentin/Documents/workspace/briefs/S9_music/labos/.venv/lib/python3.11/site-packages/keras/src/engine/training.py\", line 1303, in run_step  **\n        outputs = model.train_step(data)\n    File \"/home/payetquentin/Documents/workspace/briefs/S9_music/labos/.venv/lib/python3.11/site-packages/keras/src/engine/training.py\", line 1081, in train_step\n        loss = self.compute_loss(x, y, y_pred, sample_weight)\n    File \"/home/payetquentin/Documents/workspace/briefs/S9_music/labos/.venv/lib/python3.11/site-packages/keras/src/engine/training.py\", line 1139, in compute_loss\n        return self.compiled_loss(\n    File \"/home/payetquentin/Documents/workspace/briefs/S9_music/labos/.venv/lib/python3.11/site-packages/keras/src/engine/compile_utils.py\", line 265, in __call__\n        loss_value = loss_obj(y_t, y_p, sample_weight=sw)\n    File \"/home/payetquentin/Documents/workspace/briefs/S9_music/labos/.venv/lib/python3.11/site-packages/keras/src/losses.py\", line 142, in __call__\n        losses = call_fn(y_true, y_pred)\n    File \"/home/payetquentin/Documents/workspace/briefs/S9_music/labos/.venv/lib/python3.11/site-packages/keras/src/losses.py\", line 268, in call  **\n        return ag_fn(y_true, y_pred, **self._fn_kwargs)\n    File \"/home/payetquentin/Documents/workspace/briefs/S9_music/labos/.venv/lib/python3.11/site-packages/keras/src/losses.py\", line 2122, in categorical_crossentropy\n        return backend.categorical_crossentropy(\n    File \"/home/payetquentin/Documents/workspace/briefs/S9_music/labos/.venv/lib/python3.11/site-packages/keras/src/backend.py\", line 5560, in categorical_crossentropy\n        target.shape.assert_is_compatible_with(output.shape)\n\n    ValueError: Shapes (10, 1) and (10, 10) are incompatible\n\n\n--------------------------------------------------------------------------------\n1 fits failed with the following error:\nTraceback (most recent call last):\n  File \"/home/payetquentin/Documents/workspace/briefs/S9_music/labos/.venv/lib/python3.11/site-packages/sklearn/model_selection/_validation.py\", line 732, in _fit_and_score\n    estimator.fit(X_train, y_train, **fit_params)\n  File \"/home/payetquentin/Documents/workspace/briefs/S9_music/labos/.venv/lib/python3.11/site-packages/scikeras/wrappers.py\", line 1491, in fit\n    super().fit(X=X, y=y, sample_weight=sample_weight, **kwargs)\n  File \"/home/payetquentin/Documents/workspace/briefs/S9_music/labos/.venv/lib/python3.11/site-packages/scikeras/wrappers.py\", line 760, in fit\n    self._fit(\n  File \"/home/payetquentin/Documents/workspace/briefs/S9_music/labos/.venv/lib/python3.11/site-packages/scikeras/wrappers.py\", line 928, in _fit\n    self._fit_keras_model(\n  File \"/home/payetquentin/Documents/workspace/briefs/S9_music/labos/.venv/lib/python3.11/site-packages/scikeras/wrappers.py\", line 524, in _fit_keras_model\n    hist = self.model_.fit(x=X, y=y, **fit_args)\n           ^^^^^^^^^^^^^^^^^^^^^^^^^^^^^^^^^^^^^\n  File \"/home/payetquentin/Documents/workspace/briefs/S9_music/labos/.venv/lib/python3.11/site-packages/keras/src/utils/traceback_utils.py\", line 70, in error_handler\n    raise e.with_traceback(filtered_tb) from None\n  File \"/tmp/__autograph_generated_filelo27hx3d.py\", line 18, in tf__train_function\n    raise\nValueError: in user code:\n\n    File \"/home/payetquentin/Documents/workspace/briefs/S9_music/labos/.venv/lib/python3.11/site-packages/keras/src/engine/training.py\", line 1338, in train_function  *\n        return step_function(self, iterator)\n    File \"/home/payetquentin/Documents/workspace/briefs/S9_music/labos/.venv/lib/python3.11/site-packages/keras/src/engine/training.py\", line 1322, in step_function  **\n        outputs = model.distribute_strategy.run(run_step, args=(data,))\n    File \"/home/payetquentin/Documents/workspace/briefs/S9_music/labos/.venv/lib/python3.11/site-packages/keras/src/engine/training.py\", line 1303, in run_step  **\n        outputs = model.train_step(data)\n    File \"/home/payetquentin/Documents/workspace/briefs/S9_music/labos/.venv/lib/python3.11/site-packages/keras/src/engine/training.py\", line 1081, in train_step\n        loss = self.compute_loss(x, y, y_pred, sample_weight)\n    File \"/home/payetquentin/Documents/workspace/briefs/S9_music/labos/.venv/lib/python3.11/site-packages/keras/src/engine/training.py\", line 1139, in compute_loss\n        return self.compiled_loss(\n    File \"/home/payetquentin/Documents/workspace/briefs/S9_music/labos/.venv/lib/python3.11/site-packages/keras/src/engine/compile_utils.py\", line 265, in __call__\n        loss_value = loss_obj(y_t, y_p, sample_weight=sw)\n    File \"/home/payetquentin/Documents/workspace/briefs/S9_music/labos/.venv/lib/python3.11/site-packages/keras/src/losses.py\", line 142, in __call__\n        losses = call_fn(y_true, y_pred)\n    File \"/home/payetquentin/Documents/workspace/briefs/S9_music/labos/.venv/lib/python3.11/site-packages/keras/src/losses.py\", line 268, in call  **\n        return ag_fn(y_true, y_pred, **self._fn_kwargs)\n    File \"/home/payetquentin/Documents/workspace/briefs/S9_music/labos/.venv/lib/python3.11/site-packages/keras/src/losses.py\", line 2122, in categorical_crossentropy\n        return backend.categorical_crossentropy(\n    File \"/home/payetquentin/Documents/workspace/briefs/S9_music/labos/.venv/lib/python3.11/site-packages/keras/src/backend.py\", line 5560, in categorical_crossentropy\n        target.shape.assert_is_compatible_with(output.shape)\n\n    ValueError: Shapes (None, 1) and (None, 10) are incompatible\n\n\n--------------------------------------------------------------------------------\n1 fits failed with the following error:\nTraceback (most recent call last):\n  File \"/home/payetquentin/Documents/workspace/briefs/S9_music/labos/.venv/lib/python3.11/site-packages/sklearn/model_selection/_validation.py\", line 732, in _fit_and_score\n    estimator.fit(X_train, y_train, **fit_params)\n  File \"/home/payetquentin/Documents/workspace/briefs/S9_music/labos/.venv/lib/python3.11/site-packages/scikeras/wrappers.py\", line 1491, in fit\n    super().fit(X=X, y=y, sample_weight=sample_weight, **kwargs)\n  File \"/home/payetquentin/Documents/workspace/briefs/S9_music/labos/.venv/lib/python3.11/site-packages/scikeras/wrappers.py\", line 760, in fit\n    self._fit(\n  File \"/home/payetquentin/Documents/workspace/briefs/S9_music/labos/.venv/lib/python3.11/site-packages/scikeras/wrappers.py\", line 928, in _fit\n    self._fit_keras_model(\n  File \"/home/payetquentin/Documents/workspace/briefs/S9_music/labos/.venv/lib/python3.11/site-packages/scikeras/wrappers.py\", line 524, in _fit_keras_model\n    hist = self.model_.fit(x=X, y=y, **fit_args)\n           ^^^^^^^^^^^^^^^^^^^^^^^^^^^^^^^^^^^^^\n  File \"/home/payetquentin/Documents/workspace/briefs/S9_music/labos/.venv/lib/python3.11/site-packages/keras/src/utils/traceback_utils.py\", line 70, in error_handler\n    raise e.with_traceback(filtered_tb) from None\n  File \"/tmp/__autograph_generated_file7f7nsy67.py\", line 18, in tf__train_function\n    raise\nValueError: in user code:\n\n    File \"/home/payetquentin/Documents/workspace/briefs/S9_music/labos/.venv/lib/python3.11/site-packages/keras/src/engine/training.py\", line 1338, in train_function  *\n        return step_function(self, iterator)\n    File \"/home/payetquentin/Documents/workspace/briefs/S9_music/labos/.venv/lib/python3.11/site-packages/keras/src/engine/training.py\", line 1322, in step_function  **\n        outputs = model.distribute_strategy.run(run_step, args=(data,))\n    File \"/home/payetquentin/Documents/workspace/briefs/S9_music/labos/.venv/lib/python3.11/site-packages/keras/src/engine/training.py\", line 1303, in run_step  **\n        outputs = model.train_step(data)\n    File \"/home/payetquentin/Documents/workspace/briefs/S9_music/labos/.venv/lib/python3.11/site-packages/keras/src/engine/training.py\", line 1081, in train_step\n        loss = self.compute_loss(x, y, y_pred, sample_weight)\n    File \"/home/payetquentin/Documents/workspace/briefs/S9_music/labos/.venv/lib/python3.11/site-packages/keras/src/engine/training.py\", line 1139, in compute_loss\n        return self.compiled_loss(\n    File \"/home/payetquentin/Documents/workspace/briefs/S9_music/labos/.venv/lib/python3.11/site-packages/keras/src/engine/compile_utils.py\", line 265, in __call__\n        loss_value = loss_obj(y_t, y_p, sample_weight=sw)\n    File \"/home/payetquentin/Documents/workspace/briefs/S9_music/labos/.venv/lib/python3.11/site-packages/keras/src/losses.py\", line 142, in __call__\n        losses = call_fn(y_true, y_pred)\n    File \"/home/payetquentin/Documents/workspace/briefs/S9_music/labos/.venv/lib/python3.11/site-packages/keras/src/losses.py\", line 268, in call  **\n        return ag_fn(y_true, y_pred, **self._fn_kwargs)\n    File \"/home/payetquentin/Documents/workspace/briefs/S9_music/labos/.venv/lib/python3.11/site-packages/keras/src/losses.py\", line 2122, in categorical_crossentropy\n        return backend.categorical_crossentropy(\n    File \"/home/payetquentin/Documents/workspace/briefs/S9_music/labos/.venv/lib/python3.11/site-packages/keras/src/backend.py\", line 5560, in categorical_crossentropy\n        target.shape.assert_is_compatible_with(output.shape)\n\n    ValueError: Shapes (None, 1) and (None, 10) are incompatible\n\n\n--------------------------------------------------------------------------------\n1 fits failed with the following error:\nTraceback (most recent call last):\n  File \"/home/payetquentin/Documents/workspace/briefs/S9_music/labos/.venv/lib/python3.11/site-packages/sklearn/model_selection/_validation.py\", line 732, in _fit_and_score\n    estimator.fit(X_train, y_train, **fit_params)\n  File \"/home/payetquentin/Documents/workspace/briefs/S9_music/labos/.venv/lib/python3.11/site-packages/scikeras/wrappers.py\", line 1491, in fit\n    super().fit(X=X, y=y, sample_weight=sample_weight, **kwargs)\n  File \"/home/payetquentin/Documents/workspace/briefs/S9_music/labos/.venv/lib/python3.11/site-packages/scikeras/wrappers.py\", line 760, in fit\n    self._fit(\n  File \"/home/payetquentin/Documents/workspace/briefs/S9_music/labos/.venv/lib/python3.11/site-packages/scikeras/wrappers.py\", line 928, in _fit\n    self._fit_keras_model(\n  File \"/home/payetquentin/Documents/workspace/briefs/S9_music/labos/.venv/lib/python3.11/site-packages/scikeras/wrappers.py\", line 524, in _fit_keras_model\n    hist = self.model_.fit(x=X, y=y, **fit_args)\n           ^^^^^^^^^^^^^^^^^^^^^^^^^^^^^^^^^^^^^\n  File \"/home/payetquentin/Documents/workspace/briefs/S9_music/labos/.venv/lib/python3.11/site-packages/keras/src/utils/traceback_utils.py\", line 70, in error_handler\n    raise e.with_traceback(filtered_tb) from None\n  File \"/tmp/__autograph_generated_file6avtafmz.py\", line 18, in tf__train_function\n    raise\nValueError: in user code:\n\n    File \"/home/payetquentin/Documents/workspace/briefs/S9_music/labos/.venv/lib/python3.11/site-packages/keras/src/engine/training.py\", line 1338, in train_function  *\n        return step_function(self, iterator)\n    File \"/home/payetquentin/Documents/workspace/briefs/S9_music/labos/.venv/lib/python3.11/site-packages/keras/src/engine/training.py\", line 1322, in step_function  **\n        outputs = model.distribute_strategy.run(run_step, args=(data,))\n    File \"/home/payetquentin/Documents/workspace/briefs/S9_music/labos/.venv/lib/python3.11/site-packages/keras/src/engine/training.py\", line 1303, in run_step  **\n        outputs = model.train_step(data)\n    File \"/home/payetquentin/Documents/workspace/briefs/S9_music/labos/.venv/lib/python3.11/site-packages/keras/src/engine/training.py\", line 1081, in train_step\n        loss = self.compute_loss(x, y, y_pred, sample_weight)\n    File \"/home/payetquentin/Documents/workspace/briefs/S9_music/labos/.venv/lib/python3.11/site-packages/keras/src/engine/training.py\", line 1139, in compute_loss\n        return self.compiled_loss(\n    File \"/home/payetquentin/Documents/workspace/briefs/S9_music/labos/.venv/lib/python3.11/site-packages/keras/src/engine/compile_utils.py\", line 265, in __call__\n        loss_value = loss_obj(y_t, y_p, sample_weight=sw)\n    File \"/home/payetquentin/Documents/workspace/briefs/S9_music/labos/.venv/lib/python3.11/site-packages/keras/src/losses.py\", line 142, in __call__\n        losses = call_fn(y_true, y_pred)\n    File \"/home/payetquentin/Documents/workspace/briefs/S9_music/labos/.venv/lib/python3.11/site-packages/keras/src/losses.py\", line 268, in call  **\n        return ag_fn(y_true, y_pred, **self._fn_kwargs)\n    File \"/home/payetquentin/Documents/workspace/briefs/S9_music/labos/.venv/lib/python3.11/site-packages/keras/src/losses.py\", line 2122, in categorical_crossentropy\n        return backend.categorical_crossentropy(\n    File \"/home/payetquentin/Documents/workspace/briefs/S9_music/labos/.venv/lib/python3.11/site-packages/keras/src/backend.py\", line 5560, in categorical_crossentropy\n        target.shape.assert_is_compatible_with(output.shape)\n\n    ValueError: Shapes (10, 1) and (10, 10) are incompatible\n\n\n--------------------------------------------------------------------------------\n1 fits failed with the following error:\nTraceback (most recent call last):\n  File \"/home/payetquentin/Documents/workspace/briefs/S9_music/labos/.venv/lib/python3.11/site-packages/sklearn/model_selection/_validation.py\", line 732, in _fit_and_score\n    estimator.fit(X_train, y_train, **fit_params)\n  File \"/home/payetquentin/Documents/workspace/briefs/S9_music/labos/.venv/lib/python3.11/site-packages/scikeras/wrappers.py\", line 1491, in fit\n    super().fit(X=X, y=y, sample_weight=sample_weight, **kwargs)\n  File \"/home/payetquentin/Documents/workspace/briefs/S9_music/labos/.venv/lib/python3.11/site-packages/scikeras/wrappers.py\", line 760, in fit\n    self._fit(\n  File \"/home/payetquentin/Documents/workspace/briefs/S9_music/labos/.venv/lib/python3.11/site-packages/scikeras/wrappers.py\", line 928, in _fit\n    self._fit_keras_model(\n  File \"/home/payetquentin/Documents/workspace/briefs/S9_music/labos/.venv/lib/python3.11/site-packages/scikeras/wrappers.py\", line 524, in _fit_keras_model\n    hist = self.model_.fit(x=X, y=y, **fit_args)\n           ^^^^^^^^^^^^^^^^^^^^^^^^^^^^^^^^^^^^^\n  File \"/home/payetquentin/Documents/workspace/briefs/S9_music/labos/.venv/lib/python3.11/site-packages/keras/src/utils/traceback_utils.py\", line 70, in error_handler\n    raise e.with_traceback(filtered_tb) from None\n  File \"/tmp/__autograph_generated_filewr65263m.py\", line 18, in tf__train_function\n    raise\nValueError: in user code:\n\n    File \"/home/payetquentin/Documents/workspace/briefs/S9_music/labos/.venv/lib/python3.11/site-packages/keras/src/engine/training.py\", line 1338, in train_function  *\n        return step_function(self, iterator)\n    File \"/home/payetquentin/Documents/workspace/briefs/S9_music/labos/.venv/lib/python3.11/site-packages/keras/src/engine/training.py\", line 1322, in step_function  **\n        outputs = model.distribute_strategy.run(run_step, args=(data,))\n    File \"/home/payetquentin/Documents/workspace/briefs/S9_music/labos/.venv/lib/python3.11/site-packages/keras/src/engine/training.py\", line 1303, in run_step  **\n        outputs = model.train_step(data)\n    File \"/home/payetquentin/Documents/workspace/briefs/S9_music/labos/.venv/lib/python3.11/site-packages/keras/src/engine/training.py\", line 1081, in train_step\n        loss = self.compute_loss(x, y, y_pred, sample_weight)\n    File \"/home/payetquentin/Documents/workspace/briefs/S9_music/labos/.venv/lib/python3.11/site-packages/keras/src/engine/training.py\", line 1139, in compute_loss\n        return self.compiled_loss(\n    File \"/home/payetquentin/Documents/workspace/briefs/S9_music/labos/.venv/lib/python3.11/site-packages/keras/src/engine/compile_utils.py\", line 265, in __call__\n        loss_value = loss_obj(y_t, y_p, sample_weight=sw)\n    File \"/home/payetquentin/Documents/workspace/briefs/S9_music/labos/.venv/lib/python3.11/site-packages/keras/src/losses.py\", line 142, in __call__\n        losses = call_fn(y_true, y_pred)\n    File \"/home/payetquentin/Documents/workspace/briefs/S9_music/labos/.venv/lib/python3.11/site-packages/keras/src/losses.py\", line 268, in call  **\n        return ag_fn(y_true, y_pred, **self._fn_kwargs)\n    File \"/home/payetquentin/Documents/workspace/briefs/S9_music/labos/.venv/lib/python3.11/site-packages/keras/src/losses.py\", line 2122, in categorical_crossentropy\n        return backend.categorical_crossentropy(\n    File \"/home/payetquentin/Documents/workspace/briefs/S9_music/labos/.venv/lib/python3.11/site-packages/keras/src/backend.py\", line 5560, in categorical_crossentropy\n        target.shape.assert_is_compatible_with(output.shape)\n\n    ValueError: Shapes (None, 1) and (None, 10) are incompatible\n\n\n--------------------------------------------------------------------------------\n1 fits failed with the following error:\nTraceback (most recent call last):\n  File \"/home/payetquentin/Documents/workspace/briefs/S9_music/labos/.venv/lib/python3.11/site-packages/sklearn/model_selection/_validation.py\", line 732, in _fit_and_score\n    estimator.fit(X_train, y_train, **fit_params)\n  File \"/home/payetquentin/Documents/workspace/briefs/S9_music/labos/.venv/lib/python3.11/site-packages/scikeras/wrappers.py\", line 1491, in fit\n    super().fit(X=X, y=y, sample_weight=sample_weight, **kwargs)\n  File \"/home/payetquentin/Documents/workspace/briefs/S9_music/labos/.venv/lib/python3.11/site-packages/scikeras/wrappers.py\", line 760, in fit\n    self._fit(\n  File \"/home/payetquentin/Documents/workspace/briefs/S9_music/labos/.venv/lib/python3.11/site-packages/scikeras/wrappers.py\", line 928, in _fit\n    self._fit_keras_model(\n  File \"/home/payetquentin/Documents/workspace/briefs/S9_music/labos/.venv/lib/python3.11/site-packages/scikeras/wrappers.py\", line 524, in _fit_keras_model\n    hist = self.model_.fit(x=X, y=y, **fit_args)\n           ^^^^^^^^^^^^^^^^^^^^^^^^^^^^^^^^^^^^^\n  File \"/home/payetquentin/Documents/workspace/briefs/S9_music/labos/.venv/lib/python3.11/site-packages/keras/src/utils/traceback_utils.py\", line 70, in error_handler\n    raise e.with_traceback(filtered_tb) from None\n  File \"/tmp/__autograph_generated_filehg_x9tn0.py\", line 18, in tf__train_function\n    raise\nValueError: in user code:\n\n    File \"/home/payetquentin/Documents/workspace/briefs/S9_music/labos/.venv/lib/python3.11/site-packages/keras/src/engine/training.py\", line 1338, in train_function  *\n        return step_function(self, iterator)\n    File \"/home/payetquentin/Documents/workspace/briefs/S9_music/labos/.venv/lib/python3.11/site-packages/keras/src/engine/training.py\", line 1322, in step_function  **\n        outputs = model.distribute_strategy.run(run_step, args=(data,))\n    File \"/home/payetquentin/Documents/workspace/briefs/S9_music/labos/.venv/lib/python3.11/site-packages/keras/src/engine/training.py\", line 1303, in run_step  **\n        outputs = model.train_step(data)\n    File \"/home/payetquentin/Documents/workspace/briefs/S9_music/labos/.venv/lib/python3.11/site-packages/keras/src/engine/training.py\", line 1081, in train_step\n        loss = self.compute_loss(x, y, y_pred, sample_weight)\n    File \"/home/payetquentin/Documents/workspace/briefs/S9_music/labos/.venv/lib/python3.11/site-packages/keras/src/engine/training.py\", line 1139, in compute_loss\n        return self.compiled_loss(\n    File \"/home/payetquentin/Documents/workspace/briefs/S9_music/labos/.venv/lib/python3.11/site-packages/keras/src/engine/compile_utils.py\", line 265, in __call__\n        loss_value = loss_obj(y_t, y_p, sample_weight=sw)\n    File \"/home/payetquentin/Documents/workspace/briefs/S9_music/labos/.venv/lib/python3.11/site-packages/keras/src/losses.py\", line 142, in __call__\n        losses = call_fn(y_true, y_pred)\n    File \"/home/payetquentin/Documents/workspace/briefs/S9_music/labos/.venv/lib/python3.11/site-packages/keras/src/losses.py\", line 268, in call  **\n        return ag_fn(y_true, y_pred, **self._fn_kwargs)\n    File \"/home/payetquentin/Documents/workspace/briefs/S9_music/labos/.venv/lib/python3.11/site-packages/keras/src/losses.py\", line 2122, in categorical_crossentropy\n        return backend.categorical_crossentropy(\n    File \"/home/payetquentin/Documents/workspace/briefs/S9_music/labos/.venv/lib/python3.11/site-packages/keras/src/backend.py\", line 5560, in categorical_crossentropy\n        target.shape.assert_is_compatible_with(output.shape)\n\n    ValueError: Shapes (None, 1) and (None, 10) are incompatible\n\n\n--------------------------------------------------------------------------------\n1 fits failed with the following error:\nTraceback (most recent call last):\n  File \"/home/payetquentin/Documents/workspace/briefs/S9_music/labos/.venv/lib/python3.11/site-packages/sklearn/model_selection/_validation.py\", line 732, in _fit_and_score\n    estimator.fit(X_train, y_train, **fit_params)\n  File \"/home/payetquentin/Documents/workspace/briefs/S9_music/labos/.venv/lib/python3.11/site-packages/scikeras/wrappers.py\", line 1491, in fit\n    super().fit(X=X, y=y, sample_weight=sample_weight, **kwargs)\n  File \"/home/payetquentin/Documents/workspace/briefs/S9_music/labos/.venv/lib/python3.11/site-packages/scikeras/wrappers.py\", line 760, in fit\n    self._fit(\n  File \"/home/payetquentin/Documents/workspace/briefs/S9_music/labos/.venv/lib/python3.11/site-packages/scikeras/wrappers.py\", line 928, in _fit\n    self._fit_keras_model(\n  File \"/home/payetquentin/Documents/workspace/briefs/S9_music/labos/.venv/lib/python3.11/site-packages/scikeras/wrappers.py\", line 524, in _fit_keras_model\n    hist = self.model_.fit(x=X, y=y, **fit_args)\n           ^^^^^^^^^^^^^^^^^^^^^^^^^^^^^^^^^^^^^\n  File \"/home/payetquentin/Documents/workspace/briefs/S9_music/labos/.venv/lib/python3.11/site-packages/keras/src/utils/traceback_utils.py\", line 70, in error_handler\n    raise e.with_traceback(filtered_tb) from None\n  File \"/tmp/__autograph_generated_filec6k1v9uq.py\", line 18, in tf__train_function\n    raise\nValueError: in user code:\n\n    File \"/home/payetquentin/Documents/workspace/briefs/S9_music/labos/.venv/lib/python3.11/site-packages/keras/src/engine/training.py\", line 1338, in train_function  *\n        return step_function(self, iterator)\n    File \"/home/payetquentin/Documents/workspace/briefs/S9_music/labos/.venv/lib/python3.11/site-packages/keras/src/engine/training.py\", line 1322, in step_function  **\n        outputs = model.distribute_strategy.run(run_step, args=(data,))\n    File \"/home/payetquentin/Documents/workspace/briefs/S9_music/labos/.venv/lib/python3.11/site-packages/keras/src/engine/training.py\", line 1303, in run_step  **\n        outputs = model.train_step(data)\n    File \"/home/payetquentin/Documents/workspace/briefs/S9_music/labos/.venv/lib/python3.11/site-packages/keras/src/engine/training.py\", line 1081, in train_step\n        loss = self.compute_loss(x, y, y_pred, sample_weight)\n    File \"/home/payetquentin/Documents/workspace/briefs/S9_music/labos/.venv/lib/python3.11/site-packages/keras/src/engine/training.py\", line 1139, in compute_loss\n        return self.compiled_loss(\n    File \"/home/payetquentin/Documents/workspace/briefs/S9_music/labos/.venv/lib/python3.11/site-packages/keras/src/engine/compile_utils.py\", line 265, in __call__\n        loss_value = loss_obj(y_t, y_p, sample_weight=sw)\n    File \"/home/payetquentin/Documents/workspace/briefs/S9_music/labos/.venv/lib/python3.11/site-packages/keras/src/losses.py\", line 142, in __call__\n        losses = call_fn(y_true, y_pred)\n    File \"/home/payetquentin/Documents/workspace/briefs/S9_music/labos/.venv/lib/python3.11/site-packages/keras/src/losses.py\", line 268, in call  **\n        return ag_fn(y_true, y_pred, **self._fn_kwargs)\n    File \"/home/payetquentin/Documents/workspace/briefs/S9_music/labos/.venv/lib/python3.11/site-packages/keras/src/losses.py\", line 2122, in categorical_crossentropy\n        return backend.categorical_crossentropy(\n    File \"/home/payetquentin/Documents/workspace/briefs/S9_music/labos/.venv/lib/python3.11/site-packages/keras/src/backend.py\", line 5560, in categorical_crossentropy\n        target.shape.assert_is_compatible_with(output.shape)\n\n    ValueError: Shapes (10, 1) and (10, 10) are incompatible\n\n",
     "output_type": "error",
     "traceback": [
      "\u001b[0;31m---------------------------------------------------------------------------\u001b[0m",
      "\u001b[0;31mValueError\u001b[0m                                Traceback (most recent call last)",
      "Cell \u001b[0;32mIn[3], line 19\u001b[0m\n\u001b[1;32m     17\u001b[0m t\u001b[39m=\u001b[39mnp\u001b[39m.\u001b[39masarray(train_labels)\n\u001b[1;32m     18\u001b[0m rounded_labels\u001b[39m=\u001b[39mnp\u001b[39m.\u001b[39margmax(t, axis\u001b[39m=\u001b[39m\u001b[39m1\u001b[39m)\n\u001b[0;32m---> 19\u001b[0m grid_result \u001b[39m=\u001b[39m grid\u001b[39m.\u001b[39;49mfit(train_features, rounded_labels, verbose\u001b[39m=\u001b[39;49m\u001b[39m0\u001b[39;49m)\n\u001b[1;32m     21\u001b[0m pd_res \u001b[39m=\u001b[39m pd\u001b[39m.\u001b[39mconcat([pd\u001b[39m.\u001b[39mDataFrame(grid\u001b[39m.\u001b[39mcvresults[\u001b[39m\"\u001b[39m\u001b[39mparams\u001b[39m\u001b[39m\"\u001b[39m]),pd\u001b[39m.\u001b[39mDataFrame(grid\u001b[39m.\u001b[39mcvresults[\u001b[39m\"\u001b[39m\u001b[39mmean_test_score\u001b[39m\u001b[39m\"\u001b[39m], columns\u001b[39m=\u001b[39m[\u001b[39m\"\u001b[39m\u001b[39mAccuracy\u001b[39m\u001b[39m\"\u001b[39m])],axis\u001b[39m=\u001b[39m\u001b[39m1\u001b[39m)\n\u001b[1;32m     22\u001b[0m pd_res \u001b[39m=\u001b[39m pd_res\u001b[39m.\u001b[39msort_values(\u001b[39m'\u001b[39m\u001b[39mAccuracy\u001b[39m\u001b[39m'\u001b[39m, ascending\u001b[39m=\u001b[39m\u001b[39mFalse\u001b[39;00m)\n",
      "File \u001b[0;32m~/Documents/workspace/briefs/S9_music/labos/.venv/lib/python3.11/site-packages/sklearn/base.py:1151\u001b[0m, in \u001b[0;36m_fit_context.<locals>.decorator.<locals>.wrapper\u001b[0;34m(estimator, *args, **kwargs)\u001b[0m\n\u001b[1;32m   1144\u001b[0m     estimator\u001b[39m.\u001b[39m_validate_params()\n\u001b[1;32m   1146\u001b[0m \u001b[39mwith\u001b[39;00m config_context(\n\u001b[1;32m   1147\u001b[0m     skip_parameter_validation\u001b[39m=\u001b[39m(\n\u001b[1;32m   1148\u001b[0m         prefer_skip_nested_validation \u001b[39mor\u001b[39;00m global_skip_validation\n\u001b[1;32m   1149\u001b[0m     )\n\u001b[1;32m   1150\u001b[0m ):\n\u001b[0;32m-> 1151\u001b[0m     \u001b[39mreturn\u001b[39;00m fit_method(estimator, \u001b[39m*\u001b[39;49margs, \u001b[39m*\u001b[39;49m\u001b[39m*\u001b[39;49mkwargs)\n",
      "File \u001b[0;32m~/Documents/workspace/briefs/S9_music/labos/.venv/lib/python3.11/site-packages/sklearn/model_selection/_search.py:898\u001b[0m, in \u001b[0;36mBaseSearchCV.fit\u001b[0;34m(self, X, y, groups, **fit_params)\u001b[0m\n\u001b[1;32m    892\u001b[0m     results \u001b[39m=\u001b[39m \u001b[39mself\u001b[39m\u001b[39m.\u001b[39m_format_results(\n\u001b[1;32m    893\u001b[0m         all_candidate_params, n_splits, all_out, all_more_results\n\u001b[1;32m    894\u001b[0m     )\n\u001b[1;32m    896\u001b[0m     \u001b[39mreturn\u001b[39;00m results\n\u001b[0;32m--> 898\u001b[0m \u001b[39mself\u001b[39;49m\u001b[39m.\u001b[39;49m_run_search(evaluate_candidates)\n\u001b[1;32m    900\u001b[0m \u001b[39m# multimetric is determined here because in the case of a callable\u001b[39;00m\n\u001b[1;32m    901\u001b[0m \u001b[39m# self.scoring the return type is only known after calling\u001b[39;00m\n\u001b[1;32m    902\u001b[0m first_test_score \u001b[39m=\u001b[39m all_out[\u001b[39m0\u001b[39m][\u001b[39m\"\u001b[39m\u001b[39mtest_scores\u001b[39m\u001b[39m\"\u001b[39m]\n",
      "File \u001b[0;32m~/Documents/workspace/briefs/S9_music/labos/.venv/lib/python3.11/site-packages/sklearn/model_selection/_search.py:1419\u001b[0m, in \u001b[0;36mGridSearchCV._run_search\u001b[0;34m(self, evaluate_candidates)\u001b[0m\n\u001b[1;32m   1417\u001b[0m \u001b[39mdef\u001b[39;00m \u001b[39m_run_search\u001b[39m(\u001b[39mself\u001b[39m, evaluate_candidates):\n\u001b[1;32m   1418\u001b[0m \u001b[39m    \u001b[39m\u001b[39m\"\"\"Search all candidates in param_grid\"\"\"\u001b[39;00m\n\u001b[0;32m-> 1419\u001b[0m     evaluate_candidates(ParameterGrid(\u001b[39mself\u001b[39;49m\u001b[39m.\u001b[39;49mparam_grid))\n",
      "File \u001b[0;32m~/Documents/workspace/briefs/S9_music/labos/.venv/lib/python3.11/site-packages/sklearn/model_selection/_search.py:875\u001b[0m, in \u001b[0;36mBaseSearchCV.fit.<locals>.evaluate_candidates\u001b[0;34m(candidate_params, cv, more_results)\u001b[0m\n\u001b[1;32m    868\u001b[0m \u001b[39melif\u001b[39;00m \u001b[39mlen\u001b[39m(out) \u001b[39m!=\u001b[39m n_candidates \u001b[39m*\u001b[39m n_splits:\n\u001b[1;32m    869\u001b[0m     \u001b[39mraise\u001b[39;00m \u001b[39mValueError\u001b[39;00m(\n\u001b[1;32m    870\u001b[0m         \u001b[39m\"\u001b[39m\u001b[39mcv.split and cv.get_n_splits returned \u001b[39m\u001b[39m\"\u001b[39m\n\u001b[1;32m    871\u001b[0m         \u001b[39m\"\u001b[39m\u001b[39minconsistent results. Expected \u001b[39m\u001b[39m{}\u001b[39;00m\u001b[39m \u001b[39m\u001b[39m\"\u001b[39m\n\u001b[1;32m    872\u001b[0m         \u001b[39m\"\u001b[39m\u001b[39msplits, got \u001b[39m\u001b[39m{}\u001b[39;00m\u001b[39m\"\u001b[39m\u001b[39m.\u001b[39mformat(n_splits, \u001b[39mlen\u001b[39m(out) \u001b[39m/\u001b[39m\u001b[39m/\u001b[39m n_candidates)\n\u001b[1;32m    873\u001b[0m     )\n\u001b[0;32m--> 875\u001b[0m _warn_or_raise_about_fit_failures(out, \u001b[39mself\u001b[39;49m\u001b[39m.\u001b[39;49merror_score)\n\u001b[1;32m    877\u001b[0m \u001b[39m# For callable self.scoring, the return type is only know after\u001b[39;00m\n\u001b[1;32m    878\u001b[0m \u001b[39m# calling. If the return type is a dictionary, the error scores\u001b[39;00m\n\u001b[1;32m    879\u001b[0m \u001b[39m# can now be inserted with the correct key. The type checking\u001b[39;00m\n\u001b[1;32m    880\u001b[0m \u001b[39m# of out will be done in `_insert_error_scores`.\u001b[39;00m\n\u001b[1;32m    881\u001b[0m \u001b[39mif\u001b[39;00m \u001b[39mcallable\u001b[39m(\u001b[39mself\u001b[39m\u001b[39m.\u001b[39mscoring):\n",
      "File \u001b[0;32m~/Documents/workspace/briefs/S9_music/labos/.venv/lib/python3.11/site-packages/sklearn/model_selection/_validation.py:414\u001b[0m, in \u001b[0;36m_warn_or_raise_about_fit_failures\u001b[0;34m(results, error_score)\u001b[0m\n\u001b[1;32m    407\u001b[0m \u001b[39mif\u001b[39;00m num_failed_fits \u001b[39m==\u001b[39m num_fits:\n\u001b[1;32m    408\u001b[0m     all_fits_failed_message \u001b[39m=\u001b[39m (\n\u001b[1;32m    409\u001b[0m         \u001b[39mf\u001b[39m\u001b[39m\"\u001b[39m\u001b[39m\\n\u001b[39;00m\u001b[39mAll the \u001b[39m\u001b[39m{\u001b[39;00mnum_fits\u001b[39m}\u001b[39;00m\u001b[39m fits failed.\u001b[39m\u001b[39m\\n\u001b[39;00m\u001b[39m\"\u001b[39m\n\u001b[1;32m    410\u001b[0m         \u001b[39m\"\u001b[39m\u001b[39mIt is very likely that your model is misconfigured.\u001b[39m\u001b[39m\\n\u001b[39;00m\u001b[39m\"\u001b[39m\n\u001b[1;32m    411\u001b[0m         \u001b[39m\"\u001b[39m\u001b[39mYou can try to debug the error by setting error_score=\u001b[39m\u001b[39m'\u001b[39m\u001b[39mraise\u001b[39m\u001b[39m'\u001b[39m\u001b[39m.\u001b[39m\u001b[39m\\n\u001b[39;00m\u001b[39m\\n\u001b[39;00m\u001b[39m\"\u001b[39m\n\u001b[1;32m    412\u001b[0m         \u001b[39mf\u001b[39m\u001b[39m\"\u001b[39m\u001b[39mBelow are more details about the failures:\u001b[39m\u001b[39m\\n\u001b[39;00m\u001b[39m{\u001b[39;00mfit_errors_summary\u001b[39m}\u001b[39;00m\u001b[39m\"\u001b[39m\n\u001b[1;32m    413\u001b[0m     )\n\u001b[0;32m--> 414\u001b[0m     \u001b[39mraise\u001b[39;00m \u001b[39mValueError\u001b[39;00m(all_fits_failed_message)\n\u001b[1;32m    416\u001b[0m \u001b[39melse\u001b[39;00m:\n\u001b[1;32m    417\u001b[0m     some_fits_failed_message \u001b[39m=\u001b[39m (\n\u001b[1;32m    418\u001b[0m         \u001b[39mf\u001b[39m\u001b[39m\"\u001b[39m\u001b[39m\\n\u001b[39;00m\u001b[39m{\u001b[39;00mnum_failed_fits\u001b[39m}\u001b[39;00m\u001b[39m fits failed out of a total of \u001b[39m\u001b[39m{\u001b[39;00mnum_fits\u001b[39m}\u001b[39;00m\u001b[39m.\u001b[39m\u001b[39m\\n\u001b[39;00m\u001b[39m\"\u001b[39m\n\u001b[1;32m    419\u001b[0m         \u001b[39m\"\u001b[39m\u001b[39mThe score on these train-test partitions for these parameters\u001b[39m\u001b[39m\"\u001b[39m\n\u001b[0;32m   (...)\u001b[0m\n\u001b[1;32m    423\u001b[0m         \u001b[39mf\u001b[39m\u001b[39m\"\u001b[39m\u001b[39mBelow are more details about the failures:\u001b[39m\u001b[39m\\n\u001b[39;00m\u001b[39m{\u001b[39;00mfit_errors_summary\u001b[39m}\u001b[39;00m\u001b[39m\"\u001b[39m\n\u001b[1;32m    424\u001b[0m     )\n",
      "\u001b[0;31mValueError\u001b[0m: \nAll the 9 fits failed.\nIt is very likely that your model is misconfigured.\nYou can try to debug the error by setting error_score='raise'.\n\nBelow are more details about the failures:\n--------------------------------------------------------------------------------\n1 fits failed with the following error:\nTraceback (most recent call last):\n  File \"/home/payetquentin/Documents/workspace/briefs/S9_music/labos/.venv/lib/python3.11/site-packages/sklearn/model_selection/_validation.py\", line 732, in _fit_and_score\n    estimator.fit(X_train, y_train, **fit_params)\n  File \"/home/payetquentin/Documents/workspace/briefs/S9_music/labos/.venv/lib/python3.11/site-packages/scikeras/wrappers.py\", line 1491, in fit\n    super().fit(X=X, y=y, sample_weight=sample_weight, **kwargs)\n  File \"/home/payetquentin/Documents/workspace/briefs/S9_music/labos/.venv/lib/python3.11/site-packages/scikeras/wrappers.py\", line 760, in fit\n    self._fit(\n  File \"/home/payetquentin/Documents/workspace/briefs/S9_music/labos/.venv/lib/python3.11/site-packages/scikeras/wrappers.py\", line 928, in _fit\n    self._fit_keras_model(\n  File \"/home/payetquentin/Documents/workspace/briefs/S9_music/labos/.venv/lib/python3.11/site-packages/scikeras/wrappers.py\", line 524, in _fit_keras_model\n    hist = self.model_.fit(x=X, y=y, **fit_args)\n           ^^^^^^^^^^^^^^^^^^^^^^^^^^^^^^^^^^^^^\n  File \"/home/payetquentin/Documents/workspace/briefs/S9_music/labos/.venv/lib/python3.11/site-packages/keras/src/utils/traceback_utils.py\", line 70, in error_handler\n    raise e.with_traceback(filtered_tb) from None\n  File \"/tmp/__autograph_generated_filevsyiuivp.py\", line 18, in tf__train_function\n    raise\nValueError: in user code:\n\n    File \"/home/payetquentin/Documents/workspace/briefs/S9_music/labos/.venv/lib/python3.11/site-packages/keras/src/engine/training.py\", line 1338, in train_function  *\n        return step_function(self, iterator)\n    File \"/home/payetquentin/Documents/workspace/briefs/S9_music/labos/.venv/lib/python3.11/site-packages/keras/src/engine/training.py\", line 1322, in step_function  **\n        outputs = model.distribute_strategy.run(run_step, args=(data,))\n    File \"/home/payetquentin/Documents/workspace/briefs/S9_music/labos/.venv/lib/python3.11/site-packages/keras/src/engine/training.py\", line 1303, in run_step  **\n        outputs = model.train_step(data)\n    File \"/home/payetquentin/Documents/workspace/briefs/S9_music/labos/.venv/lib/python3.11/site-packages/keras/src/engine/training.py\", line 1081, in train_step\n        loss = self.compute_loss(x, y, y_pred, sample_weight)\n    File \"/home/payetquentin/Documents/workspace/briefs/S9_music/labos/.venv/lib/python3.11/site-packages/keras/src/engine/training.py\", line 1139, in compute_loss\n        return self.compiled_loss(\n    File \"/home/payetquentin/Documents/workspace/briefs/S9_music/labos/.venv/lib/python3.11/site-packages/keras/src/engine/compile_utils.py\", line 265, in __call__\n        loss_value = loss_obj(y_t, y_p, sample_weight=sw)\n    File \"/home/payetquentin/Documents/workspace/briefs/S9_music/labos/.venv/lib/python3.11/site-packages/keras/src/losses.py\", line 142, in __call__\n        losses = call_fn(y_true, y_pred)\n    File \"/home/payetquentin/Documents/workspace/briefs/S9_music/labos/.venv/lib/python3.11/site-packages/keras/src/losses.py\", line 268, in call  **\n        return ag_fn(y_true, y_pred, **self._fn_kwargs)\n    File \"/home/payetquentin/Documents/workspace/briefs/S9_music/labos/.venv/lib/python3.11/site-packages/keras/src/losses.py\", line 2122, in categorical_crossentropy\n        return backend.categorical_crossentropy(\n    File \"/home/payetquentin/Documents/workspace/briefs/S9_music/labos/.venv/lib/python3.11/site-packages/keras/src/backend.py\", line 5560, in categorical_crossentropy\n        target.shape.assert_is_compatible_with(output.shape)\n\n    ValueError: Shapes (None, 1) and (None, 10) are incompatible\n\n\n--------------------------------------------------------------------------------\n1 fits failed with the following error:\nTraceback (most recent call last):\n  File \"/home/payetquentin/Documents/workspace/briefs/S9_music/labos/.venv/lib/python3.11/site-packages/sklearn/model_selection/_validation.py\", line 732, in _fit_and_score\n    estimator.fit(X_train, y_train, **fit_params)\n  File \"/home/payetquentin/Documents/workspace/briefs/S9_music/labos/.venv/lib/python3.11/site-packages/scikeras/wrappers.py\", line 1491, in fit\n    super().fit(X=X, y=y, sample_weight=sample_weight, **kwargs)\n  File \"/home/payetquentin/Documents/workspace/briefs/S9_music/labos/.venv/lib/python3.11/site-packages/scikeras/wrappers.py\", line 760, in fit\n    self._fit(\n  File \"/home/payetquentin/Documents/workspace/briefs/S9_music/labos/.venv/lib/python3.11/site-packages/scikeras/wrappers.py\", line 928, in _fit\n    self._fit_keras_model(\n  File \"/home/payetquentin/Documents/workspace/briefs/S9_music/labos/.venv/lib/python3.11/site-packages/scikeras/wrappers.py\", line 524, in _fit_keras_model\n    hist = self.model_.fit(x=X, y=y, **fit_args)\n           ^^^^^^^^^^^^^^^^^^^^^^^^^^^^^^^^^^^^^\n  File \"/home/payetquentin/Documents/workspace/briefs/S9_music/labos/.venv/lib/python3.11/site-packages/keras/src/utils/traceback_utils.py\", line 70, in error_handler\n    raise e.with_traceback(filtered_tb) from None\n  File \"/tmp/__autograph_generated_filewu0bjk1n.py\", line 18, in tf__train_function\n    raise\nValueError: in user code:\n\n    File \"/home/payetquentin/Documents/workspace/briefs/S9_music/labos/.venv/lib/python3.11/site-packages/keras/src/engine/training.py\", line 1338, in train_function  *\n        return step_function(self, iterator)\n    File \"/home/payetquentin/Documents/workspace/briefs/S9_music/labos/.venv/lib/python3.11/site-packages/keras/src/engine/training.py\", line 1322, in step_function  **\n        outputs = model.distribute_strategy.run(run_step, args=(data,))\n    File \"/home/payetquentin/Documents/workspace/briefs/S9_music/labos/.venv/lib/python3.11/site-packages/keras/src/engine/training.py\", line 1303, in run_step  **\n        outputs = model.train_step(data)\n    File \"/home/payetquentin/Documents/workspace/briefs/S9_music/labos/.venv/lib/python3.11/site-packages/keras/src/engine/training.py\", line 1081, in train_step\n        loss = self.compute_loss(x, y, y_pred, sample_weight)\n    File \"/home/payetquentin/Documents/workspace/briefs/S9_music/labos/.venv/lib/python3.11/site-packages/keras/src/engine/training.py\", line 1139, in compute_loss\n        return self.compiled_loss(\n    File \"/home/payetquentin/Documents/workspace/briefs/S9_music/labos/.venv/lib/python3.11/site-packages/keras/src/engine/compile_utils.py\", line 265, in __call__\n        loss_value = loss_obj(y_t, y_p, sample_weight=sw)\n    File \"/home/payetquentin/Documents/workspace/briefs/S9_music/labos/.venv/lib/python3.11/site-packages/keras/src/losses.py\", line 142, in __call__\n        losses = call_fn(y_true, y_pred)\n    File \"/home/payetquentin/Documents/workspace/briefs/S9_music/labos/.venv/lib/python3.11/site-packages/keras/src/losses.py\", line 268, in call  **\n        return ag_fn(y_true, y_pred, **self._fn_kwargs)\n    File \"/home/payetquentin/Documents/workspace/briefs/S9_music/labos/.venv/lib/python3.11/site-packages/keras/src/losses.py\", line 2122, in categorical_crossentropy\n        return backend.categorical_crossentropy(\n    File \"/home/payetquentin/Documents/workspace/briefs/S9_music/labos/.venv/lib/python3.11/site-packages/keras/src/backend.py\", line 5560, in categorical_crossentropy\n        target.shape.assert_is_compatible_with(output.shape)\n\n    ValueError: Shapes (None, 1) and (None, 10) are incompatible\n\n\n--------------------------------------------------------------------------------\n1 fits failed with the following error:\nTraceback (most recent call last):\n  File \"/home/payetquentin/Documents/workspace/briefs/S9_music/labos/.venv/lib/python3.11/site-packages/sklearn/model_selection/_validation.py\", line 732, in _fit_and_score\n    estimator.fit(X_train, y_train, **fit_params)\n  File \"/home/payetquentin/Documents/workspace/briefs/S9_music/labos/.venv/lib/python3.11/site-packages/scikeras/wrappers.py\", line 1491, in fit\n    super().fit(X=X, y=y, sample_weight=sample_weight, **kwargs)\n  File \"/home/payetquentin/Documents/workspace/briefs/S9_music/labos/.venv/lib/python3.11/site-packages/scikeras/wrappers.py\", line 760, in fit\n    self._fit(\n  File \"/home/payetquentin/Documents/workspace/briefs/S9_music/labos/.venv/lib/python3.11/site-packages/scikeras/wrappers.py\", line 928, in _fit\n    self._fit_keras_model(\n  File \"/home/payetquentin/Documents/workspace/briefs/S9_music/labos/.venv/lib/python3.11/site-packages/scikeras/wrappers.py\", line 524, in _fit_keras_model\n    hist = self.model_.fit(x=X, y=y, **fit_args)\n           ^^^^^^^^^^^^^^^^^^^^^^^^^^^^^^^^^^^^^\n  File \"/home/payetquentin/Documents/workspace/briefs/S9_music/labos/.venv/lib/python3.11/site-packages/keras/src/utils/traceback_utils.py\", line 70, in error_handler\n    raise e.with_traceback(filtered_tb) from None\n  File \"/tmp/__autograph_generated_filexz392npo.py\", line 18, in tf__train_function\n    raise\nValueError: in user code:\n\n    File \"/home/payetquentin/Documents/workspace/briefs/S9_music/labos/.venv/lib/python3.11/site-packages/keras/src/engine/training.py\", line 1338, in train_function  *\n        return step_function(self, iterator)\n    File \"/home/payetquentin/Documents/workspace/briefs/S9_music/labos/.venv/lib/python3.11/site-packages/keras/src/engine/training.py\", line 1322, in step_function  **\n        outputs = model.distribute_strategy.run(run_step, args=(data,))\n    File \"/home/payetquentin/Documents/workspace/briefs/S9_music/labos/.venv/lib/python3.11/site-packages/keras/src/engine/training.py\", line 1303, in run_step  **\n        outputs = model.train_step(data)\n    File \"/home/payetquentin/Documents/workspace/briefs/S9_music/labos/.venv/lib/python3.11/site-packages/keras/src/engine/training.py\", line 1081, in train_step\n        loss = self.compute_loss(x, y, y_pred, sample_weight)\n    File \"/home/payetquentin/Documents/workspace/briefs/S9_music/labos/.venv/lib/python3.11/site-packages/keras/src/engine/training.py\", line 1139, in compute_loss\n        return self.compiled_loss(\n    File \"/home/payetquentin/Documents/workspace/briefs/S9_music/labos/.venv/lib/python3.11/site-packages/keras/src/engine/compile_utils.py\", line 265, in __call__\n        loss_value = loss_obj(y_t, y_p, sample_weight=sw)\n    File \"/home/payetquentin/Documents/workspace/briefs/S9_music/labos/.venv/lib/python3.11/site-packages/keras/src/losses.py\", line 142, in __call__\n        losses = call_fn(y_true, y_pred)\n    File \"/home/payetquentin/Documents/workspace/briefs/S9_music/labos/.venv/lib/python3.11/site-packages/keras/src/losses.py\", line 268, in call  **\n        return ag_fn(y_true, y_pred, **self._fn_kwargs)\n    File \"/home/payetquentin/Documents/workspace/briefs/S9_music/labos/.venv/lib/python3.11/site-packages/keras/src/losses.py\", line 2122, in categorical_crossentropy\n        return backend.categorical_crossentropy(\n    File \"/home/payetquentin/Documents/workspace/briefs/S9_music/labos/.venv/lib/python3.11/site-packages/keras/src/backend.py\", line 5560, in categorical_crossentropy\n        target.shape.assert_is_compatible_with(output.shape)\n\n    ValueError: Shapes (10, 1) and (10, 10) are incompatible\n\n\n--------------------------------------------------------------------------------\n1 fits failed with the following error:\nTraceback (most recent call last):\n  File \"/home/payetquentin/Documents/workspace/briefs/S9_music/labos/.venv/lib/python3.11/site-packages/sklearn/model_selection/_validation.py\", line 732, in _fit_and_score\n    estimator.fit(X_train, y_train, **fit_params)\n  File \"/home/payetquentin/Documents/workspace/briefs/S9_music/labos/.venv/lib/python3.11/site-packages/scikeras/wrappers.py\", line 1491, in fit\n    super().fit(X=X, y=y, sample_weight=sample_weight, **kwargs)\n  File \"/home/payetquentin/Documents/workspace/briefs/S9_music/labos/.venv/lib/python3.11/site-packages/scikeras/wrappers.py\", line 760, in fit\n    self._fit(\n  File \"/home/payetquentin/Documents/workspace/briefs/S9_music/labos/.venv/lib/python3.11/site-packages/scikeras/wrappers.py\", line 928, in _fit\n    self._fit_keras_model(\n  File \"/home/payetquentin/Documents/workspace/briefs/S9_music/labos/.venv/lib/python3.11/site-packages/scikeras/wrappers.py\", line 524, in _fit_keras_model\n    hist = self.model_.fit(x=X, y=y, **fit_args)\n           ^^^^^^^^^^^^^^^^^^^^^^^^^^^^^^^^^^^^^\n  File \"/home/payetquentin/Documents/workspace/briefs/S9_music/labos/.venv/lib/python3.11/site-packages/keras/src/utils/traceback_utils.py\", line 70, in error_handler\n    raise e.with_traceback(filtered_tb) from None\n  File \"/tmp/__autograph_generated_filelo27hx3d.py\", line 18, in tf__train_function\n    raise\nValueError: in user code:\n\n    File \"/home/payetquentin/Documents/workspace/briefs/S9_music/labos/.venv/lib/python3.11/site-packages/keras/src/engine/training.py\", line 1338, in train_function  *\n        return step_function(self, iterator)\n    File \"/home/payetquentin/Documents/workspace/briefs/S9_music/labos/.venv/lib/python3.11/site-packages/keras/src/engine/training.py\", line 1322, in step_function  **\n        outputs = model.distribute_strategy.run(run_step, args=(data,))\n    File \"/home/payetquentin/Documents/workspace/briefs/S9_music/labos/.venv/lib/python3.11/site-packages/keras/src/engine/training.py\", line 1303, in run_step  **\n        outputs = model.train_step(data)\n    File \"/home/payetquentin/Documents/workspace/briefs/S9_music/labos/.venv/lib/python3.11/site-packages/keras/src/engine/training.py\", line 1081, in train_step\n        loss = self.compute_loss(x, y, y_pred, sample_weight)\n    File \"/home/payetquentin/Documents/workspace/briefs/S9_music/labos/.venv/lib/python3.11/site-packages/keras/src/engine/training.py\", line 1139, in compute_loss\n        return self.compiled_loss(\n    File \"/home/payetquentin/Documents/workspace/briefs/S9_music/labos/.venv/lib/python3.11/site-packages/keras/src/engine/compile_utils.py\", line 265, in __call__\n        loss_value = loss_obj(y_t, y_p, sample_weight=sw)\n    File \"/home/payetquentin/Documents/workspace/briefs/S9_music/labos/.venv/lib/python3.11/site-packages/keras/src/losses.py\", line 142, in __call__\n        losses = call_fn(y_true, y_pred)\n    File \"/home/payetquentin/Documents/workspace/briefs/S9_music/labos/.venv/lib/python3.11/site-packages/keras/src/losses.py\", line 268, in call  **\n        return ag_fn(y_true, y_pred, **self._fn_kwargs)\n    File \"/home/payetquentin/Documents/workspace/briefs/S9_music/labos/.venv/lib/python3.11/site-packages/keras/src/losses.py\", line 2122, in categorical_crossentropy\n        return backend.categorical_crossentropy(\n    File \"/home/payetquentin/Documents/workspace/briefs/S9_music/labos/.venv/lib/python3.11/site-packages/keras/src/backend.py\", line 5560, in categorical_crossentropy\n        target.shape.assert_is_compatible_with(output.shape)\n\n    ValueError: Shapes (None, 1) and (None, 10) are incompatible\n\n\n--------------------------------------------------------------------------------\n1 fits failed with the following error:\nTraceback (most recent call last):\n  File \"/home/payetquentin/Documents/workspace/briefs/S9_music/labos/.venv/lib/python3.11/site-packages/sklearn/model_selection/_validation.py\", line 732, in _fit_and_score\n    estimator.fit(X_train, y_train, **fit_params)\n  File \"/home/payetquentin/Documents/workspace/briefs/S9_music/labos/.venv/lib/python3.11/site-packages/scikeras/wrappers.py\", line 1491, in fit\n    super().fit(X=X, y=y, sample_weight=sample_weight, **kwargs)\n  File \"/home/payetquentin/Documents/workspace/briefs/S9_music/labos/.venv/lib/python3.11/site-packages/scikeras/wrappers.py\", line 760, in fit\n    self._fit(\n  File \"/home/payetquentin/Documents/workspace/briefs/S9_music/labos/.venv/lib/python3.11/site-packages/scikeras/wrappers.py\", line 928, in _fit\n    self._fit_keras_model(\n  File \"/home/payetquentin/Documents/workspace/briefs/S9_music/labos/.venv/lib/python3.11/site-packages/scikeras/wrappers.py\", line 524, in _fit_keras_model\n    hist = self.model_.fit(x=X, y=y, **fit_args)\n           ^^^^^^^^^^^^^^^^^^^^^^^^^^^^^^^^^^^^^\n  File \"/home/payetquentin/Documents/workspace/briefs/S9_music/labos/.venv/lib/python3.11/site-packages/keras/src/utils/traceback_utils.py\", line 70, in error_handler\n    raise e.with_traceback(filtered_tb) from None\n  File \"/tmp/__autograph_generated_file7f7nsy67.py\", line 18, in tf__train_function\n    raise\nValueError: in user code:\n\n    File \"/home/payetquentin/Documents/workspace/briefs/S9_music/labos/.venv/lib/python3.11/site-packages/keras/src/engine/training.py\", line 1338, in train_function  *\n        return step_function(self, iterator)\n    File \"/home/payetquentin/Documents/workspace/briefs/S9_music/labos/.venv/lib/python3.11/site-packages/keras/src/engine/training.py\", line 1322, in step_function  **\n        outputs = model.distribute_strategy.run(run_step, args=(data,))\n    File \"/home/payetquentin/Documents/workspace/briefs/S9_music/labos/.venv/lib/python3.11/site-packages/keras/src/engine/training.py\", line 1303, in run_step  **\n        outputs = model.train_step(data)\n    File \"/home/payetquentin/Documents/workspace/briefs/S9_music/labos/.venv/lib/python3.11/site-packages/keras/src/engine/training.py\", line 1081, in train_step\n        loss = self.compute_loss(x, y, y_pred, sample_weight)\n    File \"/home/payetquentin/Documents/workspace/briefs/S9_music/labos/.venv/lib/python3.11/site-packages/keras/src/engine/training.py\", line 1139, in compute_loss\n        return self.compiled_loss(\n    File \"/home/payetquentin/Documents/workspace/briefs/S9_music/labos/.venv/lib/python3.11/site-packages/keras/src/engine/compile_utils.py\", line 265, in __call__\n        loss_value = loss_obj(y_t, y_p, sample_weight=sw)\n    File \"/home/payetquentin/Documents/workspace/briefs/S9_music/labos/.venv/lib/python3.11/site-packages/keras/src/losses.py\", line 142, in __call__\n        losses = call_fn(y_true, y_pred)\n    File \"/home/payetquentin/Documents/workspace/briefs/S9_music/labos/.venv/lib/python3.11/site-packages/keras/src/losses.py\", line 268, in call  **\n        return ag_fn(y_true, y_pred, **self._fn_kwargs)\n    File \"/home/payetquentin/Documents/workspace/briefs/S9_music/labos/.venv/lib/python3.11/site-packages/keras/src/losses.py\", line 2122, in categorical_crossentropy\n        return backend.categorical_crossentropy(\n    File \"/home/payetquentin/Documents/workspace/briefs/S9_music/labos/.venv/lib/python3.11/site-packages/keras/src/backend.py\", line 5560, in categorical_crossentropy\n        target.shape.assert_is_compatible_with(output.shape)\n\n    ValueError: Shapes (None, 1) and (None, 10) are incompatible\n\n\n--------------------------------------------------------------------------------\n1 fits failed with the following error:\nTraceback (most recent call last):\n  File \"/home/payetquentin/Documents/workspace/briefs/S9_music/labos/.venv/lib/python3.11/site-packages/sklearn/model_selection/_validation.py\", line 732, in _fit_and_score\n    estimator.fit(X_train, y_train, **fit_params)\n  File \"/home/payetquentin/Documents/workspace/briefs/S9_music/labos/.venv/lib/python3.11/site-packages/scikeras/wrappers.py\", line 1491, in fit\n    super().fit(X=X, y=y, sample_weight=sample_weight, **kwargs)\n  File \"/home/payetquentin/Documents/workspace/briefs/S9_music/labos/.venv/lib/python3.11/site-packages/scikeras/wrappers.py\", line 760, in fit\n    self._fit(\n  File \"/home/payetquentin/Documents/workspace/briefs/S9_music/labos/.venv/lib/python3.11/site-packages/scikeras/wrappers.py\", line 928, in _fit\n    self._fit_keras_model(\n  File \"/home/payetquentin/Documents/workspace/briefs/S9_music/labos/.venv/lib/python3.11/site-packages/scikeras/wrappers.py\", line 524, in _fit_keras_model\n    hist = self.model_.fit(x=X, y=y, **fit_args)\n           ^^^^^^^^^^^^^^^^^^^^^^^^^^^^^^^^^^^^^\n  File \"/home/payetquentin/Documents/workspace/briefs/S9_music/labos/.venv/lib/python3.11/site-packages/keras/src/utils/traceback_utils.py\", line 70, in error_handler\n    raise e.with_traceback(filtered_tb) from None\n  File \"/tmp/__autograph_generated_file6avtafmz.py\", line 18, in tf__train_function\n    raise\nValueError: in user code:\n\n    File \"/home/payetquentin/Documents/workspace/briefs/S9_music/labos/.venv/lib/python3.11/site-packages/keras/src/engine/training.py\", line 1338, in train_function  *\n        return step_function(self, iterator)\n    File \"/home/payetquentin/Documents/workspace/briefs/S9_music/labos/.venv/lib/python3.11/site-packages/keras/src/engine/training.py\", line 1322, in step_function  **\n        outputs = model.distribute_strategy.run(run_step, args=(data,))\n    File \"/home/payetquentin/Documents/workspace/briefs/S9_music/labos/.venv/lib/python3.11/site-packages/keras/src/engine/training.py\", line 1303, in run_step  **\n        outputs = model.train_step(data)\n    File \"/home/payetquentin/Documents/workspace/briefs/S9_music/labos/.venv/lib/python3.11/site-packages/keras/src/engine/training.py\", line 1081, in train_step\n        loss = self.compute_loss(x, y, y_pred, sample_weight)\n    File \"/home/payetquentin/Documents/workspace/briefs/S9_music/labos/.venv/lib/python3.11/site-packages/keras/src/engine/training.py\", line 1139, in compute_loss\n        return self.compiled_loss(\n    File \"/home/payetquentin/Documents/workspace/briefs/S9_music/labos/.venv/lib/python3.11/site-packages/keras/src/engine/compile_utils.py\", line 265, in __call__\n        loss_value = loss_obj(y_t, y_p, sample_weight=sw)\n    File \"/home/payetquentin/Documents/workspace/briefs/S9_music/labos/.venv/lib/python3.11/site-packages/keras/src/losses.py\", line 142, in __call__\n        losses = call_fn(y_true, y_pred)\n    File \"/home/payetquentin/Documents/workspace/briefs/S9_music/labos/.venv/lib/python3.11/site-packages/keras/src/losses.py\", line 268, in call  **\n        return ag_fn(y_true, y_pred, **self._fn_kwargs)\n    File \"/home/payetquentin/Documents/workspace/briefs/S9_music/labos/.venv/lib/python3.11/site-packages/keras/src/losses.py\", line 2122, in categorical_crossentropy\n        return backend.categorical_crossentropy(\n    File \"/home/payetquentin/Documents/workspace/briefs/S9_music/labos/.venv/lib/python3.11/site-packages/keras/src/backend.py\", line 5560, in categorical_crossentropy\n        target.shape.assert_is_compatible_with(output.shape)\n\n    ValueError: Shapes (10, 1) and (10, 10) are incompatible\n\n\n--------------------------------------------------------------------------------\n1 fits failed with the following error:\nTraceback (most recent call last):\n  File \"/home/payetquentin/Documents/workspace/briefs/S9_music/labos/.venv/lib/python3.11/site-packages/sklearn/model_selection/_validation.py\", line 732, in _fit_and_score\n    estimator.fit(X_train, y_train, **fit_params)\n  File \"/home/payetquentin/Documents/workspace/briefs/S9_music/labos/.venv/lib/python3.11/site-packages/scikeras/wrappers.py\", line 1491, in fit\n    super().fit(X=X, y=y, sample_weight=sample_weight, **kwargs)\n  File \"/home/payetquentin/Documents/workspace/briefs/S9_music/labos/.venv/lib/python3.11/site-packages/scikeras/wrappers.py\", line 760, in fit\n    self._fit(\n  File \"/home/payetquentin/Documents/workspace/briefs/S9_music/labos/.venv/lib/python3.11/site-packages/scikeras/wrappers.py\", line 928, in _fit\n    self._fit_keras_model(\n  File \"/home/payetquentin/Documents/workspace/briefs/S9_music/labos/.venv/lib/python3.11/site-packages/scikeras/wrappers.py\", line 524, in _fit_keras_model\n    hist = self.model_.fit(x=X, y=y, **fit_args)\n           ^^^^^^^^^^^^^^^^^^^^^^^^^^^^^^^^^^^^^\n  File \"/home/payetquentin/Documents/workspace/briefs/S9_music/labos/.venv/lib/python3.11/site-packages/keras/src/utils/traceback_utils.py\", line 70, in error_handler\n    raise e.with_traceback(filtered_tb) from None\n  File \"/tmp/__autograph_generated_filewr65263m.py\", line 18, in tf__train_function\n    raise\nValueError: in user code:\n\n    File \"/home/payetquentin/Documents/workspace/briefs/S9_music/labos/.venv/lib/python3.11/site-packages/keras/src/engine/training.py\", line 1338, in train_function  *\n        return step_function(self, iterator)\n    File \"/home/payetquentin/Documents/workspace/briefs/S9_music/labos/.venv/lib/python3.11/site-packages/keras/src/engine/training.py\", line 1322, in step_function  **\n        outputs = model.distribute_strategy.run(run_step, args=(data,))\n    File \"/home/payetquentin/Documents/workspace/briefs/S9_music/labos/.venv/lib/python3.11/site-packages/keras/src/engine/training.py\", line 1303, in run_step  **\n        outputs = model.train_step(data)\n    File \"/home/payetquentin/Documents/workspace/briefs/S9_music/labos/.venv/lib/python3.11/site-packages/keras/src/engine/training.py\", line 1081, in train_step\n        loss = self.compute_loss(x, y, y_pred, sample_weight)\n    File \"/home/payetquentin/Documents/workspace/briefs/S9_music/labos/.venv/lib/python3.11/site-packages/keras/src/engine/training.py\", line 1139, in compute_loss\n        return self.compiled_loss(\n    File \"/home/payetquentin/Documents/workspace/briefs/S9_music/labos/.venv/lib/python3.11/site-packages/keras/src/engine/compile_utils.py\", line 265, in __call__\n        loss_value = loss_obj(y_t, y_p, sample_weight=sw)\n    File \"/home/payetquentin/Documents/workspace/briefs/S9_music/labos/.venv/lib/python3.11/site-packages/keras/src/losses.py\", line 142, in __call__\n        losses = call_fn(y_true, y_pred)\n    File \"/home/payetquentin/Documents/workspace/briefs/S9_music/labos/.venv/lib/python3.11/site-packages/keras/src/losses.py\", line 268, in call  **\n        return ag_fn(y_true, y_pred, **self._fn_kwargs)\n    File \"/home/payetquentin/Documents/workspace/briefs/S9_music/labos/.venv/lib/python3.11/site-packages/keras/src/losses.py\", line 2122, in categorical_crossentropy\n        return backend.categorical_crossentropy(\n    File \"/home/payetquentin/Documents/workspace/briefs/S9_music/labos/.venv/lib/python3.11/site-packages/keras/src/backend.py\", line 5560, in categorical_crossentropy\n        target.shape.assert_is_compatible_with(output.shape)\n\n    ValueError: Shapes (None, 1) and (None, 10) are incompatible\n\n\n--------------------------------------------------------------------------------\n1 fits failed with the following error:\nTraceback (most recent call last):\n  File \"/home/payetquentin/Documents/workspace/briefs/S9_music/labos/.venv/lib/python3.11/site-packages/sklearn/model_selection/_validation.py\", line 732, in _fit_and_score\n    estimator.fit(X_train, y_train, **fit_params)\n  File \"/home/payetquentin/Documents/workspace/briefs/S9_music/labos/.venv/lib/python3.11/site-packages/scikeras/wrappers.py\", line 1491, in fit\n    super().fit(X=X, y=y, sample_weight=sample_weight, **kwargs)\n  File \"/home/payetquentin/Documents/workspace/briefs/S9_music/labos/.venv/lib/python3.11/site-packages/scikeras/wrappers.py\", line 760, in fit\n    self._fit(\n  File \"/home/payetquentin/Documents/workspace/briefs/S9_music/labos/.venv/lib/python3.11/site-packages/scikeras/wrappers.py\", line 928, in _fit\n    self._fit_keras_model(\n  File \"/home/payetquentin/Documents/workspace/briefs/S9_music/labos/.venv/lib/python3.11/site-packages/scikeras/wrappers.py\", line 524, in _fit_keras_model\n    hist = self.model_.fit(x=X, y=y, **fit_args)\n           ^^^^^^^^^^^^^^^^^^^^^^^^^^^^^^^^^^^^^\n  File \"/home/payetquentin/Documents/workspace/briefs/S9_music/labos/.venv/lib/python3.11/site-packages/keras/src/utils/traceback_utils.py\", line 70, in error_handler\n    raise e.with_traceback(filtered_tb) from None\n  File \"/tmp/__autograph_generated_filehg_x9tn0.py\", line 18, in tf__train_function\n    raise\nValueError: in user code:\n\n    File \"/home/payetquentin/Documents/workspace/briefs/S9_music/labos/.venv/lib/python3.11/site-packages/keras/src/engine/training.py\", line 1338, in train_function  *\n        return step_function(self, iterator)\n    File \"/home/payetquentin/Documents/workspace/briefs/S9_music/labos/.venv/lib/python3.11/site-packages/keras/src/engine/training.py\", line 1322, in step_function  **\n        outputs = model.distribute_strategy.run(run_step, args=(data,))\n    File \"/home/payetquentin/Documents/workspace/briefs/S9_music/labos/.venv/lib/python3.11/site-packages/keras/src/engine/training.py\", line 1303, in run_step  **\n        outputs = model.train_step(data)\n    File \"/home/payetquentin/Documents/workspace/briefs/S9_music/labos/.venv/lib/python3.11/site-packages/keras/src/engine/training.py\", line 1081, in train_step\n        loss = self.compute_loss(x, y, y_pred, sample_weight)\n    File \"/home/payetquentin/Documents/workspace/briefs/S9_music/labos/.venv/lib/python3.11/site-packages/keras/src/engine/training.py\", line 1139, in compute_loss\n        return self.compiled_loss(\n    File \"/home/payetquentin/Documents/workspace/briefs/S9_music/labos/.venv/lib/python3.11/site-packages/keras/src/engine/compile_utils.py\", line 265, in __call__\n        loss_value = loss_obj(y_t, y_p, sample_weight=sw)\n    File \"/home/payetquentin/Documents/workspace/briefs/S9_music/labos/.venv/lib/python3.11/site-packages/keras/src/losses.py\", line 142, in __call__\n        losses = call_fn(y_true, y_pred)\n    File \"/home/payetquentin/Documents/workspace/briefs/S9_music/labos/.venv/lib/python3.11/site-packages/keras/src/losses.py\", line 268, in call  **\n        return ag_fn(y_true, y_pred, **self._fn_kwargs)\n    File \"/home/payetquentin/Documents/workspace/briefs/S9_music/labos/.venv/lib/python3.11/site-packages/keras/src/losses.py\", line 2122, in categorical_crossentropy\n        return backend.categorical_crossentropy(\n    File \"/home/payetquentin/Documents/workspace/briefs/S9_music/labos/.venv/lib/python3.11/site-packages/keras/src/backend.py\", line 5560, in categorical_crossentropy\n        target.shape.assert_is_compatible_with(output.shape)\n\n    ValueError: Shapes (None, 1) and (None, 10) are incompatible\n\n\n--------------------------------------------------------------------------------\n1 fits failed with the following error:\nTraceback (most recent call last):\n  File \"/home/payetquentin/Documents/workspace/briefs/S9_music/labos/.venv/lib/python3.11/site-packages/sklearn/model_selection/_validation.py\", line 732, in _fit_and_score\n    estimator.fit(X_train, y_train, **fit_params)\n  File \"/home/payetquentin/Documents/workspace/briefs/S9_music/labos/.venv/lib/python3.11/site-packages/scikeras/wrappers.py\", line 1491, in fit\n    super().fit(X=X, y=y, sample_weight=sample_weight, **kwargs)\n  File \"/home/payetquentin/Documents/workspace/briefs/S9_music/labos/.venv/lib/python3.11/site-packages/scikeras/wrappers.py\", line 760, in fit\n    self._fit(\n  File \"/home/payetquentin/Documents/workspace/briefs/S9_music/labos/.venv/lib/python3.11/site-packages/scikeras/wrappers.py\", line 928, in _fit\n    self._fit_keras_model(\n  File \"/home/payetquentin/Documents/workspace/briefs/S9_music/labos/.venv/lib/python3.11/site-packages/scikeras/wrappers.py\", line 524, in _fit_keras_model\n    hist = self.model_.fit(x=X, y=y, **fit_args)\n           ^^^^^^^^^^^^^^^^^^^^^^^^^^^^^^^^^^^^^\n  File \"/home/payetquentin/Documents/workspace/briefs/S9_music/labos/.venv/lib/python3.11/site-packages/keras/src/utils/traceback_utils.py\", line 70, in error_handler\n    raise e.with_traceback(filtered_tb) from None\n  File \"/tmp/__autograph_generated_filec6k1v9uq.py\", line 18, in tf__train_function\n    raise\nValueError: in user code:\n\n    File \"/home/payetquentin/Documents/workspace/briefs/S9_music/labos/.venv/lib/python3.11/site-packages/keras/src/engine/training.py\", line 1338, in train_function  *\n        return step_function(self, iterator)\n    File \"/home/payetquentin/Documents/workspace/briefs/S9_music/labos/.venv/lib/python3.11/site-packages/keras/src/engine/training.py\", line 1322, in step_function  **\n        outputs = model.distribute_strategy.run(run_step, args=(data,))\n    File \"/home/payetquentin/Documents/workspace/briefs/S9_music/labos/.venv/lib/python3.11/site-packages/keras/src/engine/training.py\", line 1303, in run_step  **\n        outputs = model.train_step(data)\n    File \"/home/payetquentin/Documents/workspace/briefs/S9_music/labos/.venv/lib/python3.11/site-packages/keras/src/engine/training.py\", line 1081, in train_step\n        loss = self.compute_loss(x, y, y_pred, sample_weight)\n    File \"/home/payetquentin/Documents/workspace/briefs/S9_music/labos/.venv/lib/python3.11/site-packages/keras/src/engine/training.py\", line 1139, in compute_loss\n        return self.compiled_loss(\n    File \"/home/payetquentin/Documents/workspace/briefs/S9_music/labos/.venv/lib/python3.11/site-packages/keras/src/engine/compile_utils.py\", line 265, in __call__\n        loss_value = loss_obj(y_t, y_p, sample_weight=sw)\n    File \"/home/payetquentin/Documents/workspace/briefs/S9_music/labos/.venv/lib/python3.11/site-packages/keras/src/losses.py\", line 142, in __call__\n        losses = call_fn(y_true, y_pred)\n    File \"/home/payetquentin/Documents/workspace/briefs/S9_music/labos/.venv/lib/python3.11/site-packages/keras/src/losses.py\", line 268, in call  **\n        return ag_fn(y_true, y_pred, **self._fn_kwargs)\n    File \"/home/payetquentin/Documents/workspace/briefs/S9_music/labos/.venv/lib/python3.11/site-packages/keras/src/losses.py\", line 2122, in categorical_crossentropy\n        return backend.categorical_crossentropy(\n    File \"/home/payetquentin/Documents/workspace/briefs/S9_music/labos/.venv/lib/python3.11/site-packages/keras/src/backend.py\", line 5560, in categorical_crossentropy\n        target.shape.assert_is_compatible_with(output.shape)\n\n    ValueError: Shapes (10, 1) and (10, 10) are incompatible\n\n"
     ]
    }
   ],
   "source": [
    "def create_model(optimizer='adam'):\n",
    "    # creation du modèle\n",
    "    model = keras.models.Sequential()\n",
    "    model.add(Dense(23, input_dim=23, activation='relu'))\n",
    "    model.add(Dense(10, activation='softmax'))\n",
    "    model.compile(loss='categorical_crossentropy', optimizer=optimizer, metrics=['accuracy'])\n",
    "    return model\n",
    "\n",
    "model = KerasClassifier(build_fn=create_model, epochs=100, batch_size=10, verbose=0) #, epochs=100, batch_size=10\n",
    "\n",
    "# definition de la grille des paramètres\n",
    "optimizer = ['SGD', 'RMSprop', 'Adam'] #['SGD', 'RMSprop', 'Adagrad', 'Adadelta', 'Adam', 'Adamax', 'Nadam']\n",
    "param_grid = dict(optimizer=optimizer)\n",
    "\n",
    "grid = GridSearchCV(estimator=model, param_grid=param_grid, scoring=\"accuracy\", n_jobs=-1, cv=3)\n",
    "\n",
    "t=np.asarray(train_labels)\n",
    "rounded_labels=np.argmax(t, axis=1)\n",
    "grid_result = grid.fit(train_features, rounded_labels, verbose=0)\n",
    "\n",
    "pd_res = pd.concat([pd.DataFrame(grid.cvresults[\"params\"]),pd.DataFrame(grid.cvresults[\"mean_test_score\"], columns=[\"Accuracy\"])],axis=1)\n",
    "pd_res = pd_res.sort_values('Accuracy', ascending=False)\n",
    "pd_res.head(5)"
   ]
  }
 ],
 "metadata": {
  "kernelspec": {
   "display_name": ".venv",
   "language": "python",
   "name": "python3"
  },
  "language_info": {
   "codemirror_mode": {
    "name": "ipython",
    "version": 3
   },
   "file_extension": ".py",
   "mimetype": "text/x-python",
   "name": "python",
   "nbconvert_exporter": "python",
   "pygments_lexer": "ipython3",
   "version": "3.11.3"
  },
  "orig_nbformat": 4
 },
 "nbformat": 4,
 "nbformat_minor": 2
}
